setblock ~77~0~0 glass
setblock ~77~0~0 glass 0
setblock ~53~0~60 ice
setblock ~53~0~60 ice 0
setblock ~52~0~61 ice
setblock ~52~0~61 ice 0
setblock ~53~0~61 ice
setblock ~53~0~61 ice 0
setblock ~54~0~61 ice
setblock ~54~0~61 ice 0
setblock ~52~0~62 ice
setblock ~52~0~62 ice 0
setblock ~53~0~62 ice
setblock ~53~0~62 ice 0
setblock ~54~0~62 ice
setblock ~54~0~62 ice 0
setblock ~53~0~63 ice
setblock ~53~0~63 ice 0
setblock ~54~0~64 ice
setblock ~54~0~64 ice 0
setblock ~53~0~65 ice
setblock ~53~0~65 ice 0
setblock ~54~0~65 ice
setblock ~54~0~65 ice 0
setblock ~55~0~65 ice
setblock ~55~0~65 ice 0
setblock ~54~0~66 ice
setblock ~54~0~66 ice 0
setblock ~52~1~60 ice
setblock ~52~1~60 ice 0
setblock ~53~1~60 ice
setblock ~53~1~60 ice 0
setblock ~54~1~60 ice
setblock ~54~1~60 ice 0
setblock ~52~1~61 ice
setblock ~52~1~61 ice 0
setblock ~53~1~61 ice
setblock ~53~1~61 ice 0
setblock ~54~1~61 ice
setblock ~54~1~61 ice 0
setblock ~52~1~62 ice
setblock ~52~1~62 ice 0
setblock ~53~1~62 ice
setblock ~53~1~62 ice 0
setblock ~54~1~62 ice
setblock ~54~1~62 ice 0
setblock ~55~1~62 ice
setblock ~55~1~62 ice 0
setblock ~52~1~63 ice
setblock ~52~1~63 ice 0
setblock ~53~1~63 ice
setblock ~53~1~63 ice 0
setblock ~54~1~63 ice
setblock ~54~1~63 ice 0
setblock ~55~1~63 ice
setblock ~55~1~63 ice 0
setblock ~53~1~64 ice
setblock ~53~1~64 ice 0
setblock ~54~1~64 ice
setblock ~54~1~64 ice 0
setblock ~55~1~64 ice
setblock ~55~1~64 ice 0
setblock ~56~1~64 ice
setblock ~56~1~64 ice 0
setblock ~53~1~65 ice
setblock ~53~1~65 ice 0
setblock ~54~1~65 ice
setblock ~54~1~65 ice 0
setblock ~55~1~65 ice
setblock ~55~1~65 ice 0
setblock ~56~1~65 ice
setblock ~56~1~65 ice 0
setblock ~53~1~66 ice
setblock ~53~1~66 ice 0
setblock ~54~1~66 ice
setblock ~54~1~66 ice 0
setblock ~55~1~66 ice
setblock ~55~1~66 ice 0
setblock ~56~1~66 ice
setblock ~56~1~66 ice 0
setblock ~53~2~60 ice
setblock ~53~2~60 ice 0
setblock ~52~2~61 ice
setblock ~52~2~61 ice 0
setblock ~53~2~61 ice
setblock ~53~2~61 ice 0
setblock ~54~2~61 ice
setblock ~54~2~61 ice 0
setblock ~55~2~61 ice
setblock ~55~2~61 ice 0
setblock ~52~2~62 ice
setblock ~52~2~62 ice 0
setblock ~53~2~62 ice
setblock ~53~2~62 ice 0
setblock ~54~2~62 ice
setblock ~54~2~62 ice 0
setblock ~55~2~62 ice
setblock ~55~2~62 ice 0
setblock ~56~2~62 ice
setblock ~56~2~62 ice 0
setblock ~52~2~63 ice
setblock ~52~2~63 ice 0
setblock ~53~2~63 ice
setblock ~53~2~63 ice 0
setblock ~54~2~63 ice
setblock ~54~2~63 ice 0
setblock ~55~2~63 ice
setblock ~55~2~63 ice 0
setblock ~56~2~63 ice
setblock ~56~2~63 ice 0
setblock ~52~2~64 ice
setblock ~52~2~64 ice 0
setblock ~53~2~64 ice
setblock ~53~2~64 ice 0
setblock ~54~2~64 ice
setblock ~54~2~64 ice 0
setblock ~55~2~64 ice
setblock ~55~2~64 ice 0
setblock ~56~2~64 ice
setblock ~56~2~64 ice 0
setblock ~57~2~64 ice
setblock ~57~2~64 ice 0
setblock ~53~2~65 ice
setblock ~53~2~65 ice 0
setblock ~54~2~65 ice
setblock ~54~2~65 ice 0
setblock ~55~2~65 ice
setblock ~55~2~65 ice 0
setblock ~56~2~65 ice
setblock ~56~2~65 ice 0
setblock ~57~2~65 ice
setblock ~57~2~65 ice 0
setblock ~53~2~66 ice
setblock ~53~2~66 ice 0
setblock ~54~2~66 ice
setblock ~54~2~66 ice 0
setblock ~55~2~66 ice
setblock ~55~2~66 ice 0
setblock ~56~2~66 ice
setblock ~56~2~66 ice 0
setblock ~57~2~66 ice
setblock ~57~2~66 ice 0
setblock ~53~2~67 ice
setblock ~53~2~67 ice 0
setblock ~54~2~67 ice
setblock ~54~2~67 ice 0
setblock ~55~2~67 ice
setblock ~55~2~67 ice 0
setblock ~56~2~67 ice
setblock ~56~2~67 ice 0
setblock ~57~2~67 ice
setblock ~57~2~67 ice 0
setblock ~54~2~68 ice
setblock ~54~2~68 ice 0
setblock ~55~2~68 ice
setblock ~55~2~68 ice 0
setblock ~56~2~68 ice
setblock ~56~2~68 ice 0
setblock ~57~2~68 ice
setblock ~57~2~68 ice 0
setblock ~61~2~71 ice
setblock ~61~2~71 ice 0
setblock ~62~2~71 ice
setblock ~62~2~71 ice 0
setblock ~63~2~71 ice
setblock ~63~2~71 ice 0
setblock ~61~2~72 ice
setblock ~61~2~72 ice 0
setblock ~62~2~72 ice
setblock ~62~2~72 ice 0
setblock ~63~2~72 ice
setblock ~63~2~72 ice 0
setblock ~61~2~73 ice
setblock ~61~2~73 ice 0
setblock ~62~2~73 ice
setblock ~62~2~73 ice 0
setblock ~63~2~73 ice
setblock ~63~2~73 ice 0
setblock ~62~2~74 ice
setblock ~62~2~74 ice 0
setblock ~63~2~74 ice
setblock ~63~2~74 ice 0
setblock ~64~2~74 ice
setblock ~64~2~74 ice 0
setblock ~63~2~75 ice
setblock ~63~2~75 ice 0
setblock ~28~2~109 monster_egg
setblock ~28~2~109 monster_egg 0
setblock ~29~2~109 monster_egg
setblock ~29~2~109 monster_egg 0
setblock ~52~3~61 ice
setblock ~52~3~61 ice 0
setblock ~53~3~61 ice
setblock ~53~3~61 ice 0
setblock ~54~3~61 ice
setblock ~54~3~61 ice 0
setblock ~55~3~61 ice
setblock ~55~3~61 ice 0
setblock ~51~3~62 ice
setblock ~51~3~62 ice 0
setblock ~52~3~62 ice
setblock ~52~3~62 ice 0
setblock ~53~3~62 ice
setblock ~53~3~62 ice 0
setblock ~54~3~62 ice
setblock ~54~3~62 ice 0
setblock ~55~3~62 ice
setblock ~55~3~62 ice 0
setblock ~56~3~62 ice
setblock ~56~3~62 ice 0
setblock ~52~3~63 ice
setblock ~52~3~63 ice 0
setblock ~53~3~63 ice
setblock ~53~3~63 ice 0
setblock ~54~3~63 ice
setblock ~54~3~63 ice 0
setblock ~55~3~63 ice
setblock ~55~3~63 ice 0
setblock ~56~3~63 ice
setblock ~56~3~63 ice 0
setblock ~59~3~63 ice
setblock ~59~3~63 ice 0
setblock ~52~3~64 ice
setblock ~52~3~64 ice 0
setblock ~53~3~64 ice
setblock ~53~3~64 ice 0
setblock ~54~3~64 ice
setblock ~54~3~64 ice 0
setblock ~55~3~64 ice
setblock ~55~3~64 ice 0
setblock ~56~3~64 ice
setblock ~56~3~64 ice 0
setblock ~57~3~64 ice
setblock ~57~3~64 ice 0
setblock ~58~3~64 ice
setblock ~58~3~64 ice 0
setblock ~59~3~64 ice
setblock ~59~3~64 ice 0
setblock ~60~3~64 ice
setblock ~60~3~64 ice 0
setblock ~53~3~65 ice
setblock ~53~3~65 ice 0
setblock ~54~3~65 ice
setblock ~54~3~65 ice 0
setblock ~55~3~65 ice
setblock ~55~3~65 ice 0
setblock ~56~3~65 ice
setblock ~56~3~65 ice 0
setblock ~57~3~65 ice
setblock ~57~3~65 ice 0
setblock ~58~3~65 ice
setblock ~58~3~65 ice 0
setblock ~59~3~65 ice
setblock ~59~3~65 ice 0
setblock ~53~3~66 ice
setblock ~53~3~66 ice 0
setblock ~54~3~66 ice
setblock ~54~3~66 ice 0
setblock ~55~3~66 ice
setblock ~55~3~66 ice 0
setblock ~56~3~66 ice
setblock ~56~3~66 ice 0
setblock ~57~3~66 ice
setblock ~57~3~66 ice 0
setblock ~58~3~66 ice
setblock ~58~3~66 ice 0
setblock ~59~3~66 ice
setblock ~59~3~66 ice 0
setblock ~60~3~66 ice
setblock ~60~3~66 ice 0
setblock ~53~3~67 ice
setblock ~53~3~67 ice 0
setblock ~54~3~67 ice
setblock ~54~3~67 ice 0
setblock ~55~3~67 ice
setblock ~55~3~67 ice 0
setblock ~56~3~67 ice
setblock ~56~3~67 ice 0
setblock ~57~3~67 ice
setblock ~57~3~67 ice 0
setblock ~58~3~67 ice
setblock ~58~3~67 ice 0
setblock ~59~3~67 ice
setblock ~59~3~67 ice 0
setblock ~60~3~67 ice
setblock ~60~3~67 ice 0
setblock ~61~3~67 ice
setblock ~61~3~67 ice 0
setblock ~53~3~68 ice
setblock ~53~3~68 ice 0
setblock ~54~3~68 ice
setblock ~54~3~68 ice 0
setblock ~55~3~68 ice
setblock ~55~3~68 ice 0
setblock ~56~3~68 ice
setblock ~56~3~68 ice 0
setblock ~57~3~68 ice
setblock ~57~3~68 ice 0
setblock ~58~3~68 ice
setblock ~58~3~68 ice 0
setblock ~60~3~68 ice
setblock ~60~3~68 ice 0
setblock ~55~3~69 ice
setblock ~55~3~69 ice 0
setblock ~56~3~69 ice
setblock ~56~3~69 ice 0
setblock ~57~3~69 ice
setblock ~57~3~69 ice 0
setblock ~59~3~70 ice
setblock ~59~3~70 ice 0
setblock ~60~3~70 ice
setblock ~60~3~70 ice 0
setblock ~61~3~70 ice
setblock ~61~3~70 ice 0
setblock ~62~3~70 ice
setblock ~62~3~70 ice 0
setblock ~63~3~70 ice
setblock ~63~3~70 ice 0
setblock ~64~3~70 ice
setblock ~64~3~70 ice 0
setblock ~59~3~71 ice
setblock ~59~3~71 ice 0
setblock ~60~3~71 ice
setblock ~60~3~71 ice 0
setblock ~61~3~71 ice
setblock ~61~3~71 ice 0
setblock ~62~3~71 ice
setblock ~62~3~71 ice 0
setblock ~63~3~71 ice
setblock ~63~3~71 ice 0
setblock ~64~3~71 ice
setblock ~64~3~71 ice 0
setblock ~65~3~71 ice
setblock ~65~3~71 ice 0
setblock ~59~3~72 ice
setblock ~59~3~72 ice 0
setblock ~60~3~72 ice
setblock ~60~3~72 ice 0
setblock ~61~3~72 ice
setblock ~61~3~72 ice 0
setblock ~62~3~72 ice
setblock ~62~3~72 ice 0
setblock ~63~3~72 ice
setblock ~63~3~72 ice 0
setblock ~64~3~72 ice
setblock ~64~3~72 ice 0
setblock ~60~3~73 ice
setblock ~60~3~73 ice 0
setblock ~61~3~73 ice
setblock ~61~3~73 ice 0
setblock ~62~3~73 ice
setblock ~62~3~73 ice 0
setblock ~63~3~73 ice
setblock ~63~3~73 ice 0
setblock ~64~3~73 ice
setblock ~64~3~73 ice 0
setblock ~61~3~74 ice
setblock ~61~3~74 ice 0
setblock ~62~3~74 ice
setblock ~62~3~74 ice 0
setblock ~63~3~74 ice
setblock ~63~3~74 ice 0
setblock ~64~3~74 ice
setblock ~64~3~74 ice 0
setblock ~62~3~75 ice
setblock ~62~3~75 ice 0
setblock ~63~3~75 ice
setblock ~63~3~75 ice 0
setblock ~64~3~75 ice
setblock ~64~3~75 ice 0
setblock ~28~3~108 monster_egg
setblock ~28~3~108 monster_egg 0
setblock ~27~3~109 monster_egg
setblock ~27~3~109 monster_egg 0
setblock ~28~3~109 monster_egg
setblock ~28~3~109 monster_egg 0
setblock ~29~3~109 monster_egg
setblock ~29~3~109 monster_egg 0
setblock ~30~3~109 monster_egg
setblock ~30~3~109 monster_egg 0
setblock ~28~4~18 ice
setblock ~28~4~18 ice 0
setblock ~27~4~19 ice
setblock ~27~4~19 ice 0
setblock ~28~4~19 ice
setblock ~28~4~19 ice 0
setblock ~29~4~19 ice
setblock ~29~4~19 ice 0
setblock ~28~4~20 ice
setblock ~28~4~20 ice 0
setblock ~57~4~58 ice
setblock ~57~4~58 ice 0
setblock ~56~4~59 ice
setblock ~56~4~59 ice 0
setblock ~57~4~59 ice
setblock ~57~4~59 ice 0
setblock ~58~4~59 ice
setblock ~58~4~59 ice 0
setblock ~59~4~59 ice
setblock ~59~4~59 ice 0
setblock ~57~4~60 ice
setblock ~57~4~60 ice 0
setblock ~58~4~60 ice
setblock ~58~4~60 ice 0
setblock ~59~4~60 ice
setblock ~59~4~60 ice 0
setblock ~60~4~60 ice
setblock ~60~4~60 ice 0
setblock ~51~4~61 ice
setblock ~51~4~61 ice 0
setblock ~52~4~61 ice
setblock ~52~4~61 ice 0
setblock ~53~4~61 ice
setblock ~53~4~61 ice 0
setblock ~54~4~61 ice
setblock ~54~4~61 ice 0
setblock ~55~4~61 ice
setblock ~55~4~61 ice 0
setblock ~59~4~61 ice
setblock ~59~4~61 ice 0
setblock ~63~4~61 ice
setblock ~63~4~61 ice 0
setblock ~65~4~61 ice
setblock ~65~4~61 ice 0
setblock ~51~4~62 ice
setblock ~51~4~62 ice 0
setblock ~52~4~62 ice
setblock ~52~4~62 ice 0
setblock ~53~4~62 ice
setblock ~53~4~62 ice 0
setblock ~54~4~62 ice
setblock ~54~4~62 ice 0
setblock ~55~4~62 ice
setblock ~55~4~62 ice 0
setblock ~56~4~62 ice
setblock ~56~4~62 ice 0
setblock ~62~4~62 ice
setblock ~62~4~62 ice 0
setblock ~63~4~62 ice
setblock ~63~4~62 ice 0
setblock ~64~4~62 ice
setblock ~64~4~62 ice 0
setblock ~65~4~62 ice
setblock ~65~4~62 ice 0
setblock ~66~4~62 ice
setblock ~66~4~62 ice 0
setblock ~51~4~63 ice
setblock ~51~4~63 ice 0
setblock ~52~4~63 ice
setblock ~52~4~63 ice 0
setblock ~53~4~63 ice
setblock ~53~4~63 ice 0
setblock ~54~4~63 ice
setblock ~54~4~63 ice 0
setblock ~55~4~63 ice
setblock ~55~4~63 ice 0
setblock ~56~4~63 ice
setblock ~56~4~63 ice 0
setblock ~58~4~63 ice
setblock ~58~4~63 ice 0
setblock ~59~4~63 ice
setblock ~59~4~63 ice 0
setblock ~60~4~63 ice
setblock ~60~4~63 ice 0
setblock ~62~4~63 ice
setblock ~62~4~63 ice 0
setblock ~63~4~63 ice
setblock ~63~4~63 ice 0
setblock ~64~4~63 ice
setblock ~64~4~63 ice 0
setblock ~65~4~63 ice
setblock ~65~4~63 ice 0
setblock ~52~4~64 ice
setblock ~52~4~64 ice 0
setblock ~53~4~64 ice
setblock ~53~4~64 ice 0
setblock ~54~4~64 ice
setblock ~54~4~64 ice 0
setblock ~55~4~64 ice
setblock ~55~4~64 ice 0
setblock ~56~4~64 ice
setblock ~56~4~64 ice 0
setblock ~57~4~64 ice
setblock ~57~4~64 ice 0
setblock ~58~4~64 ice
setblock ~58~4~64 ice 0
setblock ~59~4~64 ice
setblock ~59~4~64 ice 0
setblock ~60~4~64 ice
setblock ~60~4~64 ice 0
setblock ~62~4~64 ice
setblock ~62~4~64 ice 0
setblock ~63~4~64 ice
setblock ~63~4~64 ice 0
setblock ~64~4~64 ice
setblock ~64~4~64 ice 0
setblock ~53~4~65 ice
setblock ~53~4~65 ice 0
setblock ~54~4~65 ice
setblock ~54~4~65 ice 0
setblock ~55~4~65 ice
setblock ~55~4~65 ice 0
setblock ~56~4~65 ice
setblock ~56~4~65 ice 0
setblock ~57~4~65 ice
setblock ~57~4~65 ice 0
setblock ~58~4~65 ice
setblock ~58~4~65 ice 0
setblock ~59~4~65 ice
setblock ~59~4~65 ice 0
setblock ~60~4~65 ice
setblock ~60~4~65 ice 0
setblock ~53~4~66 ice
setblock ~53~4~66 ice 0
setblock ~54~4~66 ice
setblock ~54~4~66 ice 0
setblock ~55~4~66 ice
setblock ~55~4~66 ice 0
setblock ~56~4~66 ice
setblock ~56~4~66 ice 0
setblock ~57~4~66 ice
setblock ~57~4~66 ice 0
setblock ~58~4~66 ice
setblock ~58~4~66 ice 0
setblock ~59~4~66 ice
setblock ~59~4~66 ice 0
setblock ~60~4~66 ice
setblock ~60~4~66 ice 0
setblock ~61~4~66 ice
setblock ~61~4~66 ice 0
setblock ~53~4~67 ice
setblock ~53~4~67 ice 0
setblock ~54~4~67 ice
setblock ~54~4~67 ice 0
setblock ~55~4~67 ice
setblock ~55~4~67 ice 0
setblock ~56~4~67 ice
setblock ~56~4~67 ice 0
setblock ~57~4~67 ice
setblock ~57~4~67 ice 0
setblock ~58~4~67 ice
setblock ~58~4~67 ice 0
setblock ~59~4~67 ice
setblock ~59~4~67 ice 0
setblock ~60~4~67 ice
setblock ~60~4~67 ice 0
setblock ~61~4~67 ice
setblock ~61~4~67 ice 0
setblock ~62~4~67 ice
setblock ~62~4~67 ice 0
setblock ~54~4~68 ice
setblock ~54~4~68 ice 0
setblock ~55~4~68 ice
setblock ~55~4~68 ice 0
setblock ~56~4~68 ice
setblock ~56~4~68 ice 0
setblock ~57~4~68 ice
setblock ~57~4~68 ice 0
setblock ~58~4~68 ice
setblock ~58~4~68 ice 0
setblock ~59~4~68 ice
setblock ~59~4~68 ice 0
setblock ~60~4~68 ice
setblock ~60~4~68 ice 0
setblock ~61~4~68 ice
setblock ~61~4~68 ice 0
setblock ~55~4~69 ice
setblock ~55~4~69 ice 0
setblock ~56~4~69 ice
setblock ~56~4~69 ice 0
setblock ~57~4~69 ice
setblock ~57~4~69 ice 0
setblock ~59~4~69 ice
setblock ~59~4~69 ice 0
setblock ~60~4~69 ice
setblock ~60~4~69 ice 0
setblock ~61~4~69 ice
setblock ~61~4~69 ice 0
setblock ~56~4~70 ice
setblock ~56~4~70 ice 0
setblock ~58~4~70 ice
setblock ~58~4~70 ice 0
setblock ~59~4~70 ice
setblock ~59~4~70 ice 0
setblock ~60~4~70 ice
setblock ~60~4~70 ice 0
setblock ~61~4~70 ice
setblock ~61~4~70 ice 0
setblock ~62~4~70 ice
setblock ~62~4~70 ice 0
setblock ~63~4~70 ice
setblock ~63~4~70 ice 0
setblock ~64~4~70 ice
setblock ~64~4~70 ice 0
setblock ~65~4~70 ice
setblock ~65~4~70 ice 0
setblock ~58~4~71 ice
setblock ~58~4~71 ice 0
setblock ~59~4~71 ice
setblock ~59~4~71 ice 0
setblock ~60~4~71 ice
setblock ~60~4~71 ice 0
setblock ~61~4~71 ice
setblock ~61~4~71 ice 0
setblock ~62~4~71 ice
setblock ~62~4~71 ice 0
setblock ~63~4~71 ice
setblock ~63~4~71 ice 0
setblock ~64~4~71 ice
setblock ~64~4~71 ice 0
setblock ~65~4~71 ice
setblock ~65~4~71 ice 0
setblock ~58~4~72 ice
setblock ~58~4~72 ice 0
setblock ~59~4~72 ice
setblock ~59~4~72 ice 0
setblock ~60~4~72 ice
setblock ~60~4~72 ice 0
setblock ~61~4~72 ice
setblock ~61~4~72 ice 0
setblock ~62~4~72 ice
setblock ~62~4~72 ice 0
setblock ~63~4~72 ice
setblock ~63~4~72 ice 0
setblock ~64~4~72 ice
setblock ~64~4~72 ice 0
setblock ~65~4~72 ice
setblock ~65~4~72 ice 0
setblock ~59~4~73 ice
setblock ~59~4~73 ice 0
setblock ~60~4~73 ice
setblock ~60~4~73 ice 0
setblock ~61~4~73 ice
setblock ~61~4~73 ice 0
setblock ~62~4~73 ice
setblock ~62~4~73 ice 0
setblock ~63~4~73 ice
setblock ~63~4~73 ice 0
setblock ~64~4~73 ice
setblock ~64~4~73 ice 0
setblock ~61~4~74 ice
setblock ~61~4~74 ice 0
setblock ~62~4~74 ice
setblock ~62~4~74 ice 0
setblock ~63~4~74 ice
setblock ~63~4~74 ice 0
setblock ~64~4~74 ice
setblock ~64~4~74 ice 0
setblock ~63~4~75 ice
setblock ~63~4~75 ice 0
setblock ~44~4~82 ice
setblock ~44~4~82 ice 0
setblock ~43~4~83 ice
setblock ~43~4~83 ice 0
setblock ~44~4~83 ice
setblock ~44~4~83 ice 0
setblock ~45~4~83 ice
setblock ~45~4~83 ice 0
setblock ~44~4~84 ice
setblock ~44~4~84 ice 0
setblock ~28~4~108 monster_egg
setblock ~28~4~108 monster_egg 0
setblock ~29~4~108 monster_egg
setblock ~29~4~108 monster_egg 0
setblock ~30~4~108 monster_egg
setblock ~30~4~108 monster_egg 0
setblock ~27~4~109 monster_egg
setblock ~27~4~109 monster_egg 0
setblock ~28~4~109 monster_egg
setblock ~28~4~109 monster_egg 0
setblock ~29~4~109 monster_egg
setblock ~29~4~109 monster_egg 0
setblock ~30~4~109 monster_egg
setblock ~30~4~109 monster_egg 0
setblock ~31~4~109 monster_egg
setblock ~31~4~109 monster_egg 0
setblock ~27~5~17 ice
setblock ~27~5~17 ice 0
setblock ~28~5~17 ice
setblock ~28~5~17 ice 0
setblock ~26~5~18 ice
setblock ~26~5~18 ice 0
setblock ~27~5~18 ice
setblock ~27~5~18 ice 0
setblock ~28~5~18 ice
setblock ~28~5~18 ice 0
setblock ~29~5~18 ice
setblock ~29~5~18 ice 0
setblock ~26~5~19 ice
setblock ~26~5~19 ice 0
setblock ~27~5~19 ice
setblock ~27~5~19 ice 0
setblock ~28~5~19 ice
setblock ~28~5~19 ice 0
setblock ~29~5~19 ice
setblock ~29~5~19 ice 0
setblock ~27~5~20 ice
setblock ~27~5~20 ice 0
setblock ~28~5~20 ice
setblock ~28~5~20 ice 0
setblock ~29~5~20 ice
setblock ~29~5~20 ice 0
setblock ~27~5~21 ice
setblock ~27~5~21 ice 0
setblock ~28~5~21 ice
setblock ~28~5~21 ice 0
setblock ~29~5~21 ice
setblock ~29~5~21 ice 0
setblock ~27~5~22 ice
setblock ~27~5~22 ice 0
setblock ~28~5~22 ice
setblock ~28~5~22 ice 0
setblock ~29~5~22 ice
setblock ~29~5~22 ice 0
setblock ~56~5~58 ice
setblock ~56~5~58 ice 0
setblock ~57~5~58 ice
setblock ~57~5~58 ice 0
setblock ~58~5~58 ice
setblock ~58~5~58 ice 0
setblock ~56~5~59 ice
setblock ~56~5~59 ice 0
setblock ~57~5~59 ice
setblock ~57~5~59 ice 0
setblock ~58~5~59 ice
setblock ~58~5~59 ice 0
setblock ~59~5~59 ice
setblock ~59~5~59 ice 0
setblock ~60~5~59 ice
setblock ~60~5~59 ice 0
setblock ~56~5~60 ice
setblock ~56~5~60 ice 0
setblock ~57~5~60 ice
setblock ~57~5~60 ice 0
setblock ~58~5~60 ice
setblock ~58~5~60 ice 0
setblock ~59~5~60 ice
setblock ~59~5~60 ice 0
setblock ~60~5~60 ice
setblock ~60~5~60 ice 0
setblock ~52~5~61 ice
setblock ~52~5~61 ice 0
setblock ~57~5~61 ice
setblock ~57~5~61 ice 0
setblock ~58~5~61 ice
setblock ~58~5~61 ice 0
setblock ~59~5~61 ice
setblock ~59~5~61 ice 0
setblock ~60~5~61 ice
setblock ~60~5~61 ice 0
setblock ~62~5~61 ice
setblock ~62~5~61 ice 0
setblock ~63~5~61 ice
setblock ~63~5~61 ice 0
setblock ~64~5~61 ice
setblock ~64~5~61 ice 0
setblock ~65~5~61 ice
setblock ~65~5~61 ice 0
setblock ~66~5~61 ice
setblock ~66~5~61 ice 0
setblock ~51~5~62 ice
setblock ~51~5~62 ice 0
setblock ~52~5~62 ice
setblock ~52~5~62 ice 0
setblock ~53~5~62 ice
setblock ~53~5~62 ice 0
setblock ~54~5~62 ice
setblock ~54~5~62 ice 0
setblock ~55~5~62 ice
setblock ~55~5~62 ice 0
setblock ~57~5~62 ice
setblock ~57~5~62 ice 0
setblock ~58~5~62 ice
setblock ~58~5~62 ice 0
setblock ~59~5~62 ice
setblock ~59~5~62 ice 0
setblock ~60~5~62 ice
setblock ~60~5~62 ice 0
setblock ~61~5~62 ice
setblock ~61~5~62 ice 0
setblock ~62~5~62 ice
setblock ~62~5~62 ice 0
setblock ~63~5~62 ice
setblock ~63~5~62 ice 0
setblock ~64~5~62 ice
setblock ~64~5~62 ice 0
setblock ~65~5~62 ice
setblock ~65~5~62 ice 0
setblock ~66~5~62 ice
setblock ~66~5~62 ice 0
setblock ~52~5~63 ice
setblock ~52~5~63 ice 0
setblock ~53~5~63 ice
setblock ~53~5~63 ice 0
setblock ~54~5~63 ice
setblock ~54~5~63 ice 0
setblock ~55~5~63 ice
setblock ~55~5~63 ice 0
setblock ~57~5~63 ice
setblock ~57~5~63 ice 0
setblock ~58~5~63 ice
setblock ~58~5~63 ice 0
setblock ~59~5~63 ice
setblock ~59~5~63 ice 0
setblock ~60~5~63 ice
setblock ~60~5~63 ice 0
setblock ~61~5~63 ice
setblock ~61~5~63 ice 0
setblock ~62~5~63 ice
setblock ~62~5~63 ice 0
setblock ~63~5~63 ice
setblock ~63~5~63 ice 0
setblock ~64~5~63 ice
setblock ~64~5~63 ice 0
setblock ~65~5~63 ice
setblock ~65~5~63 ice 0
setblock ~66~5~63 ice
setblock ~66~5~63 ice 0
setblock ~53~5~64 ice
setblock ~53~5~64 ice 0
setblock ~54~5~64 ice
setblock ~54~5~64 ice 0
setblock ~55~5~64 ice
setblock ~55~5~64 ice 0
setblock ~56~5~64 ice
setblock ~56~5~64 ice 0
setblock ~57~5~64 ice
setblock ~57~5~64 ice 0
setblock ~58~5~64 ice
setblock ~58~5~64 ice 0
setblock ~59~5~64 ice
setblock ~59~5~64 ice 0
setblock ~60~5~64 ice
setblock ~60~5~64 ice 0
setblock ~61~5~64 ice
setblock ~61~5~64 ice 0
setblock ~62~5~64 ice
setblock ~62~5~64 ice 0
setblock ~63~5~64 ice
setblock ~63~5~64 ice 0
setblock ~64~5~64 ice
setblock ~64~5~64 ice 0
setblock ~65~5~64 ice
setblock ~65~5~64 ice 0
setblock ~54~5~65 ice
setblock ~54~5~65 ice 0
setblock ~55~5~65 ice
setblock ~55~5~65 ice 0
setblock ~56~5~65 ice
setblock ~56~5~65 ice 0
setblock ~57~5~65 ice
setblock ~57~5~65 ice 0
setblock ~58~5~65 ice
setblock ~58~5~65 ice 0
setblock ~59~5~65 ice
setblock ~59~5~65 ice 0
setblock ~60~5~65 ice
setblock ~60~5~65 ice 0
setblock ~62~5~65 ice
setblock ~62~5~65 ice 0
setblock ~63~5~65 ice
setblock ~63~5~65 ice 0
setblock ~64~5~65 ice
setblock ~64~5~65 ice 0
setblock ~54~5~66 ice
setblock ~54~5~66 ice 0
setblock ~55~5~66 ice
setblock ~55~5~66 ice 0
setblock ~56~5~66 ice
setblock ~56~5~66 ice 0
setblock ~57~5~66 ice
setblock ~57~5~66 ice 0
setblock ~58~5~66 ice
setblock ~58~5~66 ice 0
setblock ~59~5~66 ice
setblock ~59~5~66 ice 0
setblock ~60~5~66 ice
setblock ~60~5~66 ice 0
setblock ~61~5~66 ice
setblock ~61~5~66 ice 0
setblock ~62~5~66 ice
setblock ~62~5~66 ice 0
setblock ~54~5~67 ice
setblock ~54~5~67 ice 0
setblock ~55~5~67 ice
setblock ~55~5~67 ice 0
setblock ~56~5~67 ice
setblock ~56~5~67 ice 0
setblock ~57~5~67 ice
setblock ~57~5~67 ice 0
setblock ~58~5~67 ice
setblock ~58~5~67 ice 0
setblock ~59~5~67 ice
setblock ~59~5~67 ice 0
setblock ~60~5~67 ice
setblock ~60~5~67 ice 0
setblock ~61~5~67 ice
setblock ~61~5~67 ice 0
setblock ~62~5~67 ice
setblock ~62~5~67 ice 0
setblock ~63~5~67 ice
setblock ~63~5~67 ice 0
setblock ~54~5~68 ice
setblock ~54~5~68 ice 0
setblock ~55~5~68 ice
setblock ~55~5~68 ice 0
setblock ~56~5~68 ice
setblock ~56~5~68 ice 0
setblock ~57~5~68 ice
setblock ~57~5~68 ice 0
setblock ~58~5~68 ice
setblock ~58~5~68 ice 0
setblock ~59~5~68 ice
setblock ~59~5~68 ice 0
setblock ~60~5~68 ice
setblock ~60~5~68 ice 0
setblock ~61~5~68 ice
setblock ~61~5~68 ice 0
setblock ~62~5~68 ice
setblock ~62~5~68 ice 0
setblock ~63~5~68 ice
setblock ~63~5~68 ice 0
setblock ~64~5~68 ice
setblock ~64~5~68 ice 0
setblock ~55~5~69 ice
setblock ~55~5~69 ice 0
setblock ~56~5~69 ice
setblock ~56~5~69 ice 0
setblock ~57~5~69 ice
setblock ~57~5~69 ice 0
setblock ~58~5~69 ice
setblock ~58~5~69 ice 0
setblock ~59~5~69 ice
setblock ~59~5~69 ice 0
setblock ~60~5~69 ice
setblock ~60~5~69 ice 0
setblock ~61~5~69 ice
setblock ~61~5~69 ice 0
setblock ~62~5~69 ice
setblock ~62~5~69 ice 0
setblock ~63~5~69 ice
setblock ~63~5~69 ice 0
setblock ~55~5~70 ice
setblock ~55~5~70 ice 0
setblock ~56~5~70 ice
setblock ~56~5~70 ice 0
setblock ~57~5~70 ice
setblock ~57~5~70 ice 0
setblock ~58~5~70 ice
setblock ~58~5~70 ice 0
setblock ~59~5~70 ice
setblock ~59~5~70 ice 0
setblock ~60~5~70 ice
setblock ~60~5~70 ice 0
setblock ~61~5~70 ice
setblock ~61~5~70 ice 0
setblock ~62~5~70 ice
setblock ~62~5~70 ice 0
setblock ~63~5~70 ice
setblock ~63~5~70 ice 0
setblock ~64~5~70 ice
setblock ~64~5~70 ice 0
setblock ~58~5~71 ice
setblock ~58~5~71 ice 0
setblock ~59~5~71 ice
setblock ~59~5~71 ice 0
setblock ~60~5~71 ice
setblock ~60~5~71 ice 0
setblock ~61~5~71 ice
setblock ~61~5~71 ice 0
setblock ~62~5~71 ice
setblock ~62~5~71 ice 0
setblock ~63~5~71 ice
setblock ~63~5~71 ice 0
setblock ~64~5~71 ice
setblock ~64~5~71 ice 0
setblock ~65~5~71 ice
setblock ~65~5~71 ice 0
setblock ~58~5~72 ice
setblock ~58~5~72 ice 0
setblock ~59~5~72 ice
setblock ~59~5~72 ice 0
setblock ~60~5~72 ice
setblock ~60~5~72 ice 0
setblock ~61~5~72 ice
setblock ~61~5~72 ice 0
setblock ~62~5~72 ice
setblock ~62~5~72 ice 0
setblock ~63~5~72 ice
setblock ~63~5~72 ice 0
setblock ~64~5~72 ice
setblock ~64~5~72 ice 0
setblock ~59~5~73 ice
setblock ~59~5~73 ice 0
setblock ~60~5~73 ice
setblock ~60~5~73 ice 0
setblock ~61~5~73 ice
setblock ~61~5~73 ice 0
setblock ~62~5~73 ice
setblock ~62~5~73 ice 0
setblock ~63~5~73 ice
setblock ~63~5~73 ice 0
setblock ~64~5~73 ice
setblock ~64~5~73 ice 0
setblock ~61~5~74 ice
setblock ~61~5~74 ice 0
setblock ~62~5~74 ice
setblock ~62~5~74 ice 0
setblock ~63~5~74 ice
setblock ~63~5~74 ice 0
setblock ~43~5~82 ice
setblock ~43~5~82 ice 0
setblock ~44~5~82 ice
setblock ~44~5~82 ice 0
setblock ~45~5~82 ice
setblock ~45~5~82 ice 0
setblock ~43~5~83 ice
setblock ~43~5~83 ice 0
setblock ~44~5~83 ice
setblock ~44~5~83 ice 0
setblock ~45~5~83 ice
setblock ~45~5~83 ice 0
setblock ~43~5~84 ice
setblock ~43~5~84 ice 0
setblock ~44~5~84 ice
setblock ~44~5~84 ice 0
setblock ~45~5~84 ice
setblock ~45~5~84 ice 0
setblock ~43~5~85 ice
setblock ~43~5~85 ice 0
setblock ~44~5~85 ice
setblock ~44~5~85 ice 0
setblock ~45~5~85 ice
setblock ~45~5~85 ice 0
setblock ~27~5~108 monster_egg
setblock ~27~5~108 monster_egg 0
setblock ~28~5~108 monster_egg
setblock ~28~5~108 monster_egg 0
setblock ~29~5~108 monster_egg
setblock ~29~5~108 monster_egg 0
setblock ~30~5~108 monster_egg
setblock ~30~5~108 monster_egg 0
setblock ~27~5~109 monster_egg
setblock ~27~5~109 monster_egg 0
setblock ~28~5~109 monster_egg
setblock ~28~5~109 monster_egg 0
setblock ~29~5~109 monster_egg
setblock ~29~5~109 monster_egg 0
setblock ~30~5~109 monster_egg
setblock ~30~5~109 monster_egg 0
setblock ~31~5~109 monster_egg
setblock ~31~5~109 monster_egg 0
setblock ~27~6~16 ice
setblock ~27~6~16 ice 0
setblock ~28~6~16 ice
setblock ~28~6~16 ice 0
setblock ~26~6~17 ice
setblock ~26~6~17 ice 0
setblock ~27~6~17 ice
setblock ~27~6~17 ice 0
setblock ~28~6~17 ice
setblock ~28~6~17 ice 0
setblock ~29~6~17 ice
setblock ~29~6~17 ice 0
setblock ~25~6~18 ice
setblock ~25~6~18 ice 0
setblock ~26~6~18 ice
setblock ~26~6~18 ice 0
setblock ~27~6~18 ice
setblock ~27~6~18 ice 0
setblock ~28~6~18 ice
setblock ~28~6~18 ice 0
setblock ~29~6~18 ice
setblock ~29~6~18 ice 0
setblock ~25~6~19 ice
setblock ~25~6~19 ice 0
setblock ~26~6~19 ice
setblock ~26~6~19 ice 0
setblock ~27~6~19 ice
setblock ~27~6~19 ice 0
setblock ~28~6~19 ice
setblock ~28~6~19 ice 0
setblock ~29~6~19 ice
setblock ~29~6~19 ice 0
setblock ~26~6~20 ice
setblock ~26~6~20 ice 0
setblock ~27~6~20 ice
setblock ~27~6~20 ice 0
setblock ~28~6~20 ice
setblock ~28~6~20 ice 0
setblock ~29~6~20 ice
setblock ~29~6~20 ice 0
setblock ~30~6~20 ice
setblock ~30~6~20 ice 0
setblock ~26~6~21 ice
setblock ~26~6~21 ice 0
setblock ~27~6~21 ice
setblock ~27~6~21 ice 0
setblock ~28~6~21 ice
setblock ~28~6~21 ice 0
setblock ~29~6~21 ice
setblock ~29~6~21 ice 0
setblock ~30~6~21 ice
setblock ~30~6~21 ice 0
setblock ~26~6~22 ice
setblock ~26~6~22 ice 0
setblock ~27~6~22 ice
setblock ~27~6~22 ice 0
setblock ~28~6~22 ice
setblock ~28~6~22 ice 0
setblock ~29~6~22 ice
setblock ~29~6~22 ice 0
setblock ~30~6~22 ice
setblock ~30~6~22 ice 0
setblock ~27~6~23 ice
setblock ~27~6~23 ice 0
setblock ~28~6~23 ice
setblock ~28~6~23 ice 0
setblock ~29~6~23 ice
setblock ~29~6~23 ice 0
setblock ~8~6~47 ice
setblock ~8~6~47 ice 0
setblock ~9~6~47 ice
setblock ~9~6~47 ice 0
setblock ~10~6~47 ice
setblock ~10~6~47 ice 0
setblock ~8~6~48 ice
setblock ~8~6~48 ice 0
setblock ~9~6~48 ice
setblock ~9~6~48 ice 0
setblock ~10~6~48 ice
setblock ~10~6~48 ice 0
setblock ~8~6~49 ice
setblock ~8~6~49 ice 0
setblock ~9~6~49 ice
setblock ~9~6~49 ice 0
setblock ~10~6~49 ice
setblock ~10~6~49 ice 0
setblock ~57~6~58 ice
setblock ~57~6~58 ice 0
setblock ~56~6~59 ice
setblock ~56~6~59 ice 0
setblock ~57~6~59 ice
setblock ~57~6~59 ice 0
setblock ~58~6~59 ice
setblock ~58~6~59 ice 0
setblock ~59~6~59 ice
setblock ~59~6~59 ice 0
setblock ~60~6~59 ice
setblock ~60~6~59 ice 0
setblock ~56~6~60 ice
setblock ~56~6~60 ice 0
setblock ~57~6~60 ice
setblock ~57~6~60 ice 0
setblock ~58~6~60 ice
setblock ~58~6~60 ice 0
setblock ~59~6~60 ice
setblock ~59~6~60 ice 0
setblock ~60~6~60 ice
setblock ~60~6~60 ice 0
setblock ~61~6~60 ice
setblock ~61~6~60 ice 0
setblock ~56~6~61 ice
setblock ~56~6~61 ice 0
setblock ~57~6~61 ice
setblock ~57~6~61 ice 0
setblock ~58~6~61 ice
setblock ~58~6~61 ice 0
setblock ~59~6~61 ice
setblock ~59~6~61 ice 0
setblock ~60~6~61 ice
setblock ~60~6~61 ice 0
setblock ~62~6~61 ice
setblock ~62~6~61 ice 0
setblock ~63~6~61 ice
setblock ~63~6~61 ice 0
setblock ~64~6~61 ice
setblock ~64~6~61 ice 0
setblock ~65~6~61 ice
setblock ~65~6~61 ice 0
setblock ~55~6~62 ice
setblock ~55~6~62 ice 0
setblock ~56~6~62 ice
setblock ~56~6~62 ice 0
setblock ~57~6~62 ice
setblock ~57~6~62 ice 0
setblock ~58~6~62 ice
setblock ~58~6~62 ice 0
setblock ~59~6~62 ice
setblock ~59~6~62 ice 0
setblock ~60~6~62 ice
setblock ~60~6~62 ice 0
setblock ~61~6~62 ice
setblock ~61~6~62 ice 0
setblock ~62~6~62 ice
setblock ~62~6~62 ice 0
setblock ~63~6~62 ice
setblock ~63~6~62 ice 0
setblock ~64~6~62 ice
setblock ~64~6~62 ice 0
setblock ~65~6~62 ice
setblock ~65~6~62 ice 0
setblock ~66~6~62 ice
setblock ~66~6~62 ice 0
setblock ~55~6~63 ice
setblock ~55~6~63 ice 0
setblock ~56~6~63 ice
setblock ~56~6~63 ice 0
setblock ~57~6~63 ice
setblock ~57~6~63 ice 0
setblock ~58~6~63 ice
setblock ~58~6~63 ice 0
setblock ~59~6~63 ice
setblock ~59~6~63 ice 0
setblock ~60~6~63 ice
setblock ~60~6~63 ice 0
setblock ~61~6~63 ice
setblock ~61~6~63 ice 0
setblock ~62~6~63 ice
setblock ~62~6~63 ice 0
setblock ~63~6~63 ice
setblock ~63~6~63 ice 0
setblock ~64~6~63 ice
setblock ~64~6~63 ice 0
setblock ~65~6~63 ice
setblock ~65~6~63 ice 0
setblock ~54~6~64 ice
setblock ~54~6~64 ice 0
setblock ~55~6~64 ice
setblock ~55~6~64 ice 0
setblock ~56~6~64 ice
setblock ~56~6~64 ice 0
setblock ~57~6~64 ice
setblock ~57~6~64 ice 0
setblock ~58~6~64 ice
setblock ~58~6~64 ice 0
setblock ~59~6~64 ice
setblock ~59~6~64 ice 0
setblock ~60~6~64 ice
setblock ~60~6~64 ice 0
setblock ~61~6~64 ice
setblock ~61~6~64 ice 0
setblock ~62~6~64 ice
setblock ~62~6~64 ice 0
setblock ~63~6~64 ice
setblock ~63~6~64 ice 0
setblock ~64~6~64 ice
setblock ~64~6~64 ice 0
setblock ~65~6~64 ice
setblock ~65~6~64 ice 0
setblock ~54~6~65 ice
setblock ~54~6~65 ice 0
setblock ~55~6~65 ice
setblock ~55~6~65 ice 0
setblock ~56~6~65 ice
setblock ~56~6~65 ice 0
setblock ~57~6~65 ice
setblock ~57~6~65 ice 0
setblock ~58~6~65 ice
setblock ~58~6~65 ice 0
setblock ~59~6~65 ice
setblock ~59~6~65 ice 0
setblock ~60~6~65 ice
setblock ~60~6~65 ice 0
setblock ~61~6~65 ice
setblock ~61~6~65 ice 0
setblock ~62~6~65 ice
setblock ~62~6~65 ice 0
setblock ~63~6~65 ice
setblock ~63~6~65 ice 0
setblock ~64~6~65 ice
setblock ~64~6~65 ice 0
setblock ~54~6~66 ice
setblock ~54~6~66 ice 0
setblock ~55~6~66 ice
setblock ~55~6~66 ice 0
setblock ~56~6~66 ice
setblock ~56~6~66 ice 0
setblock ~57~6~66 ice
setblock ~57~6~66 ice 0
setblock ~58~6~66 ice
setblock ~58~6~66 ice 0
setblock ~59~6~66 ice
setblock ~59~6~66 ice 0
setblock ~60~6~66 ice
setblock ~60~6~66 ice 0
setblock ~61~6~66 ice
setblock ~61~6~66 ice 0
setblock ~53~6~67 ice
setblock ~53~6~67 ice 0
setblock ~54~6~67 ice
setblock ~54~6~67 ice 0
setblock ~55~6~67 ice
setblock ~55~6~67 ice 0
setblock ~56~6~67 ice
setblock ~56~6~67 ice 0
setblock ~57~6~67 ice
setblock ~57~6~67 ice 0
setblock ~58~6~67 ice
setblock ~58~6~67 ice 0
setblock ~59~6~67 ice
setblock ~59~6~67 ice 0
setblock ~60~6~67 ice
setblock ~60~6~67 ice 0
setblock ~61~6~67 ice
setblock ~61~6~67 ice 0
setblock ~62~6~67 ice
setblock ~62~6~67 ice 0
setblock ~63~6~67 ice
setblock ~63~6~67 ice 0
setblock ~64~6~67 ice
setblock ~64~6~67 ice 0
setblock ~54~6~68 ice
setblock ~54~6~68 ice 0
setblock ~55~6~68 ice
setblock ~55~6~68 ice 0
setblock ~56~6~68 ice
setblock ~56~6~68 ice 0
setblock ~57~6~68 ice
setblock ~57~6~68 ice 0
setblock ~58~6~68 ice
setblock ~58~6~68 ice 0
setblock ~59~6~68 ice
setblock ~59~6~68 ice 0
setblock ~60~6~68 ice
setblock ~60~6~68 ice 0
setblock ~61~6~68 ice
setblock ~61~6~68 ice 0
setblock ~62~6~68 ice
setblock ~62~6~68 ice 0
setblock ~63~6~68 ice
setblock ~63~6~68 ice 0
setblock ~64~6~68 ice
setblock ~64~6~68 ice 0
setblock ~55~6~69 ice
setblock ~55~6~69 ice 0
setblock ~56~6~69 ice
setblock ~56~6~69 ice 0
setblock ~57~6~69 ice
setblock ~57~6~69 ice 0
setblock ~58~6~69 ice
setblock ~58~6~69 ice 0
setblock ~59~6~69 ice
setblock ~59~6~69 ice 0
setblock ~60~6~69 ice
setblock ~60~6~69 ice 0
setblock ~61~6~69 ice
setblock ~61~6~69 ice 0
setblock ~62~6~69 ice
setblock ~62~6~69 ice 0
setblock ~63~6~69 ice
setblock ~63~6~69 ice 0
setblock ~64~6~69 ice
setblock ~64~6~69 ice 0
setblock ~56~6~70 ice
setblock ~56~6~70 ice 0
setblock ~57~6~70 ice
setblock ~57~6~70 ice 0
setblock ~58~6~70 ice
setblock ~58~6~70 ice 0
setblock ~59~6~70 ice
setblock ~59~6~70 ice 0
setblock ~60~6~70 ice
setblock ~60~6~70 ice 0
setblock ~61~6~70 ice
setblock ~61~6~70 ice 0
setblock ~62~6~70 ice
setblock ~62~6~70 ice 0
setblock ~63~6~70 ice
setblock ~63~6~70 ice 0
setblock ~57~6~71 ice
setblock ~57~6~71 ice 0
setblock ~58~6~71 ice
setblock ~58~6~71 ice 0
setblock ~59~6~71 ice
setblock ~59~6~71 ice 0
setblock ~60~6~71 ice
setblock ~60~6~71 ice 0
setblock ~61~6~71 ice
setblock ~61~6~71 ice 0
setblock ~62~6~71 ice
setblock ~62~6~71 ice 0
setblock ~63~6~71 ice
setblock ~63~6~71 ice 0
setblock ~58~6~72 ice
setblock ~58~6~72 ice 0
setblock ~59~6~72 ice
setblock ~59~6~72 ice 0
setblock ~60~6~72 ice
setblock ~60~6~72 ice 0
setblock ~61~6~72 ice
setblock ~61~6~72 ice 0
setblock ~62~6~72 ice
setblock ~62~6~72 ice 0
setblock ~63~6~72 ice
setblock ~63~6~72 ice 0
setblock ~59~6~73 ice
setblock ~59~6~73 ice 0
setblock ~60~6~73 ice
setblock ~60~6~73 ice 0
setblock ~61~6~73 ice
setblock ~61~6~73 ice 0
setblock ~62~6~73 ice
setblock ~62~6~73 ice 0
setblock ~63~6~73 ice
setblock ~63~6~73 ice 0
setblock ~43~6~81 ice
setblock ~43~6~81 ice 0
setblock ~42~6~82 ice
setblock ~42~6~82 ice 0
setblock ~43~6~82 ice
setblock ~43~6~82 ice 0
setblock ~44~6~82 ice
setblock ~44~6~82 ice 0
setblock ~45~6~82 ice
setblock ~45~6~82 ice 0
setblock ~42~6~83 ice
setblock ~42~6~83 ice 0
setblock ~43~6~83 ice
setblock ~43~6~83 ice 0
setblock ~44~6~83 ice
setblock ~44~6~83 ice 0
setblock ~45~6~83 ice
setblock ~45~6~83 ice 0
setblock ~46~6~83 ice
setblock ~46~6~83 ice 0
setblock ~6~6~84 ice
setblock ~6~6~84 ice 0
setblock ~39~6~84 ice
setblock ~39~6~84 ice 0
setblock ~40~6~84 ice
setblock ~40~6~84 ice 0
setblock ~42~6~84 ice
setblock ~42~6~84 ice 0
setblock ~43~6~84 ice
setblock ~43~6~84 ice 0
setblock ~44~6~84 ice
setblock ~44~6~84 ice 0
setblock ~45~6~84 ice
setblock ~45~6~84 ice 0
setblock ~46~6~84 ice
setblock ~46~6~84 ice 0
setblock ~5~6~85 ice
setblock ~5~6~85 ice 0
setblock ~6~6~85 ice
setblock ~6~6~85 ice 0
setblock ~7~6~85 ice
setblock ~7~6~85 ice 0
setblock ~38~6~85 ice
setblock ~38~6~85 ice 0
setblock ~39~6~85 ice
setblock ~39~6~85 ice 0
setblock ~40~6~85 ice
setblock ~40~6~85 ice 0
setblock ~41~6~85 ice
setblock ~41~6~85 ice 0
setblock ~42~6~85 ice
setblock ~42~6~85 ice 0
setblock ~43~6~85 ice
setblock ~43~6~85 ice 0
setblock ~44~6~85 ice
setblock ~44~6~85 ice 0
setblock ~45~6~85 ice
setblock ~45~6~85 ice 0
setblock ~46~6~85 ice
setblock ~46~6~85 ice 0
setblock ~6~6~86 ice
setblock ~6~6~86 ice 0
setblock ~39~6~86 ice
setblock ~39~6~86 ice 0
setblock ~40~6~86 ice
setblock ~40~6~86 ice 0
setblock ~41~6~86 ice
setblock ~41~6~86 ice 0
setblock ~42~6~86 ice
setblock ~42~6~86 ice 0
setblock ~43~6~86 ice
setblock ~43~6~86 ice 0
setblock ~44~6~86 ice
setblock ~44~6~86 ice 0
setblock ~45~6~86 ice
setblock ~45~6~86 ice 0
setblock ~40~6~87 ice
setblock ~40~6~87 ice 0
setblock ~41~6~87 ice
setblock ~41~6~87 ice 0
setblock ~42~6~87 ice
setblock ~42~6~87 ice 0
setblock ~40~6~88 ice
setblock ~40~6~88 ice 0
setblock ~41~6~88 ice
setblock ~41~6~88 ice 0
setblock ~42~6~88 ice
setblock ~42~6~88 ice 0
setblock ~27~6~108 monster_egg
setblock ~27~6~108 monster_egg 0
setblock ~28~6~108 monster_egg
setblock ~28~6~108 monster_egg 0
setblock ~29~6~108 monster_egg
setblock ~29~6~108 monster_egg 0
setblock ~30~6~108 monster_egg
setblock ~30~6~108 monster_egg 0
setblock ~31~6~108 monster_egg
setblock ~31~6~108 monster_egg 0
setblock ~27~6~109 monster_egg
setblock ~27~6~109 monster_egg 0
setblock ~28~6~109 monster_egg
setblock ~28~6~109 monster_egg 0
setblock ~29~6~109 monster_egg
setblock ~29~6~109 monster_egg 0
setblock ~30~6~109 monster_egg
setblock ~30~6~109 monster_egg 0
setblock ~31~6~109 monster_egg
setblock ~31~6~109 monster_egg 0
setblock ~27~7~16 ice
setblock ~27~7~16 ice 0
setblock ~28~7~16 ice
setblock ~28~7~16 ice 0
setblock ~25~7~17 ice
setblock ~25~7~17 ice 0
setblock ~26~7~17 ice
setblock ~26~7~17 ice 0
setblock ~27~7~17 ice
setblock ~27~7~17 ice 0
setblock ~28~7~17 ice
setblock ~28~7~17 ice 0
setblock ~29~7~17 ice
setblock ~29~7~17 ice 0
setblock ~25~7~18 ice
setblock ~25~7~18 ice 0
setblock ~26~7~18 ice
setblock ~26~7~18 ice 0
setblock ~27~7~18 ice
setblock ~27~7~18 ice 0
setblock ~28~7~18 ice
setblock ~28~7~18 ice 0
setblock ~29~7~18 ice
setblock ~29~7~18 ice 0
setblock ~25~7~19 ice
setblock ~25~7~19 ice 0
setblock ~26~7~19 ice
setblock ~26~7~19 ice 0
setblock ~27~7~19 ice
setblock ~27~7~19 ice 0
setblock ~28~7~19 ice
setblock ~28~7~19 ice 0
setblock ~29~7~19 ice
setblock ~29~7~19 ice 0
setblock ~32~7~19 ice
setblock ~32~7~19 ice 0
setblock ~24~7~20 ice
setblock ~24~7~20 ice 0
setblock ~25~7~20 ice
setblock ~25~7~20 ice 0
setblock ~26~7~20 ice
setblock ~26~7~20 ice 0
setblock ~27~7~20 ice
setblock ~27~7~20 ice 0
setblock ~28~7~20 ice
setblock ~28~7~20 ice 0
setblock ~29~7~20 ice
setblock ~29~7~20 ice 0
setblock ~30~7~20 ice
setblock ~30~7~20 ice 0
setblock ~31~7~20 ice
setblock ~31~7~20 ice 0
setblock ~32~7~20 ice
setblock ~32~7~20 ice 0
setblock ~33~7~20 ice
setblock ~33~7~20 ice 0
setblock ~24~7~21 ice
setblock ~24~7~21 ice 0
setblock ~25~7~21 ice
setblock ~25~7~21 ice 0
setblock ~26~7~21 ice
setblock ~26~7~21 ice 0
setblock ~27~7~21 ice
setblock ~27~7~21 ice 0
setblock ~28~7~21 ice
setblock ~28~7~21 ice 0
setblock ~29~7~21 ice
setblock ~29~7~21 ice 0
setblock ~30~7~21 ice
setblock ~30~7~21 ice 0
setblock ~32~7~21 ice
setblock ~32~7~21 ice 0
setblock ~24~7~22 ice
setblock ~24~7~22 ice 0
setblock ~25~7~22 ice
setblock ~25~7~22 ice 0
setblock ~26~7~22 ice
setblock ~26~7~22 ice 0
setblock ~27~7~22 ice
setblock ~27~7~22 ice 0
setblock ~28~7~22 ice
setblock ~28~7~22 ice 0
setblock ~29~7~22 ice
setblock ~29~7~22 ice 0
setblock ~30~7~22 ice
setblock ~30~7~22 ice 0
setblock ~27~7~23 ice
setblock ~27~7~23 ice 0
setblock ~28~7~23 ice
setblock ~28~7~23 ice 0
setblock ~29~7~23 ice
setblock ~29~7~23 ice 0
setblock ~8~7~45 ice
setblock ~8~7~45 ice 0
setblock ~9~7~45 ice
setblock ~9~7~45 ice 0
setblock ~10~7~45 ice
setblock ~10~7~45 ice 0
setblock ~8~7~46 ice
setblock ~8~7~46 ice 0
setblock ~9~7~46 ice
setblock ~9~7~46 ice 0
setblock ~10~7~46 ice
setblock ~10~7~46 ice 0
setblock ~13~7~46 ice
setblock ~13~7~46 ice 0
setblock ~14~7~46 ice
setblock ~14~7~46 ice 0
setblock ~15~7~46 ice
setblock ~15~7~46 ice 0
setblock ~7~7~47 ice
setblock ~7~7~47 ice 0
setblock ~8~7~47 ice
setblock ~8~7~47 ice 0
setblock ~9~7~47 ice
setblock ~9~7~47 ice 0
setblock ~10~7~47 ice
setblock ~10~7~47 ice 0
setblock ~11~7~47 ice
setblock ~11~7~47 ice 0
setblock ~13~7~47 ice
setblock ~13~7~47 ice 0
setblock ~14~7~47 ice
setblock ~14~7~47 ice 0
setblock ~15~7~47 ice
setblock ~15~7~47 ice 0
setblock ~7~7~48 ice
setblock ~7~7~48 ice 0
setblock ~8~7~48 ice
setblock ~8~7~48 ice 0
setblock ~9~7~48 ice
setblock ~9~7~48 ice 0
setblock ~10~7~48 ice
setblock ~10~7~48 ice 0
setblock ~11~7~48 ice
setblock ~11~7~48 ice 0
setblock ~13~7~48 ice
setblock ~13~7~48 ice 0
setblock ~14~7~48 ice
setblock ~14~7~48 ice 0
setblock ~15~7~48 ice
setblock ~15~7~48 ice 0
setblock ~6~7~49 ice
setblock ~6~7~49 ice 0
setblock ~7~7~49 ice
setblock ~7~7~49 ice 0
setblock ~8~7~49 ice
setblock ~8~7~49 ice 0
setblock ~9~7~49 ice
setblock ~9~7~49 ice 0
setblock ~10~7~49 ice
setblock ~10~7~49 ice 0
setblock ~11~7~49 ice
setblock ~11~7~49 ice 0
setblock ~7~7~50 ice
setblock ~7~7~50 ice 0
setblock ~8~7~50 ice
setblock ~8~7~50 ice 0
setblock ~9~7~50 ice
setblock ~9~7~50 ice 0
setblock ~10~7~50 ice
setblock ~10~7~50 ice 0
setblock ~57~7~59 ice
setblock ~57~7~59 ice 0
setblock ~59~7~59 ice
setblock ~59~7~59 ice 0
setblock ~60~7~59 ice
setblock ~60~7~59 ice 0
setblock ~61~7~59 ice
setblock ~61~7~59 ice 0
setblock ~56~7~60 ice
setblock ~56~7~60 ice 0
setblock ~57~7~60 ice
setblock ~57~7~60 ice 0
setblock ~58~7~60 ice
setblock ~58~7~60 ice 0
setblock ~59~7~60 ice
setblock ~59~7~60 ice 0
setblock ~60~7~60 ice
setblock ~60~7~60 ice 0
setblock ~61~7~60 ice
setblock ~61~7~60 ice 0
setblock ~54~7~61 ice
setblock ~54~7~61 ice 0
setblock ~55~7~61 ice
setblock ~55~7~61 ice 0
setblock ~56~7~61 ice
setblock ~56~7~61 ice 0
setblock ~57~7~61 ice
setblock ~57~7~61 ice 0
setblock ~58~7~61 ice
setblock ~58~7~61 ice 0
setblock ~59~7~61 ice
setblock ~59~7~61 ice 0
setblock ~60~7~61 ice
setblock ~60~7~61 ice 0
setblock ~61~7~61 ice
setblock ~61~7~61 ice 0
setblock ~62~7~61 ice
setblock ~62~7~61 ice 0
setblock ~63~7~61 ice
setblock ~63~7~61 ice 0
setblock ~64~7~61 ice
setblock ~64~7~61 ice 0
setblock ~53~7~62 ice
setblock ~53~7~62 ice 0
setblock ~54~7~62 ice
setblock ~54~7~62 ice 0
setblock ~55~7~62 ice
setblock ~55~7~62 ice 0
setblock ~56~7~62 ice
setblock ~56~7~62 ice 0
setblock ~57~7~62 ice
setblock ~57~7~62 ice 0
setblock ~58~7~62 ice
setblock ~58~7~62 ice 0
setblock ~59~7~62 ice
setblock ~59~7~62 ice 0
setblock ~60~7~62 ice
setblock ~60~7~62 ice 0
setblock ~61~7~62 ice
setblock ~61~7~62 ice 0
setblock ~62~7~62 ice
setblock ~62~7~62 ice 0
setblock ~63~7~62 ice
setblock ~63~7~62 ice 0
setblock ~64~7~62 ice
setblock ~64~7~62 ice 0
setblock ~65~7~62 ice
setblock ~65~7~62 ice 0
setblock ~54~7~63 ice
setblock ~54~7~63 ice 0
setblock ~55~7~63 ice
setblock ~55~7~63 ice 0
setblock ~56~7~63 ice
setblock ~56~7~63 ice 0
setblock ~57~7~63 ice
setblock ~57~7~63 ice 0
setblock ~58~7~63 ice
setblock ~58~7~63 ice 0
setblock ~59~7~63 ice
setblock ~59~7~63 ice 0
setblock ~60~7~63 ice
setblock ~60~7~63 ice 0
setblock ~61~7~63 ice
setblock ~61~7~63 ice 0
setblock ~62~7~63 ice
setblock ~62~7~63 ice 0
setblock ~63~7~63 ice
setblock ~63~7~63 ice 0
setblock ~64~7~63 ice
setblock ~64~7~63 ice 0
setblock ~65~7~63 ice
setblock ~65~7~63 ice 0
setblock ~53~7~64 ice
setblock ~53~7~64 ice 0
setblock ~54~7~64 ice
setblock ~54~7~64 ice 0
setblock ~55~7~64 ice
setblock ~55~7~64 ice 0
setblock ~56~7~64 ice
setblock ~56~7~64 ice 0
setblock ~57~7~64 ice
setblock ~57~7~64 ice 0
setblock ~58~7~64 ice
setblock ~58~7~64 ice 0
setblock ~59~7~64 ice
setblock ~59~7~64 ice 0
setblock ~60~7~64 ice
setblock ~60~7~64 ice 0
setblock ~61~7~64 ice
setblock ~61~7~64 ice 0
setblock ~62~7~64 ice
setblock ~62~7~64 ice 0
setblock ~63~7~64 ice
setblock ~63~7~64 ice 0
setblock ~64~7~64 ice
setblock ~64~7~64 ice 0
setblock ~65~7~64 ice
setblock ~65~7~64 ice 0
setblock ~53~7~65 ice
setblock ~53~7~65 ice 0
setblock ~54~7~65 ice
setblock ~54~7~65 ice 0
setblock ~55~7~65 ice
setblock ~55~7~65 ice 0
setblock ~56~7~65 ice
setblock ~56~7~65 ice 0
setblock ~57~7~65 ice
setblock ~57~7~65 ice 0
setblock ~58~7~65 ice
setblock ~58~7~65 ice 0
setblock ~59~7~65 ice
setblock ~59~7~65 ice 0
setblock ~60~7~65 ice
setblock ~60~7~65 ice 0
setblock ~61~7~65 ice
setblock ~61~7~65 ice 0
setblock ~62~7~65 ice
setblock ~62~7~65 ice 0
setblock ~63~7~65 ice
setblock ~63~7~65 ice 0
setblock ~64~7~65 ice
setblock ~64~7~65 ice 0
setblock ~53~7~66 ice
setblock ~53~7~66 ice 0
setblock ~54~7~66 ice
setblock ~54~7~66 ice 0
setblock ~55~7~66 ice
setblock ~55~7~66 ice 0
setblock ~56~7~66 ice
setblock ~56~7~66 ice 0
setblock ~57~7~66 ice
setblock ~57~7~66 ice 0
setblock ~58~7~66 ice
setblock ~58~7~66 ice 0
setblock ~59~7~66 ice
setblock ~59~7~66 ice 0
setblock ~60~7~66 ice
setblock ~60~7~66 ice 0
setblock ~61~7~66 ice
setblock ~61~7~66 ice 0
setblock ~62~7~66 ice
setblock ~62~7~66 ice 0
setblock ~63~7~66 ice
setblock ~63~7~66 ice 0
setblock ~53~7~67 ice
setblock ~53~7~67 ice 0
setblock ~54~7~67 ice
setblock ~54~7~67 ice 0
setblock ~55~7~67 ice
setblock ~55~7~67 ice 0
setblock ~56~7~67 ice
setblock ~56~7~67 ice 0
setblock ~57~7~67 ice
setblock ~57~7~67 ice 0
setblock ~58~7~67 ice
setblock ~58~7~67 ice 0
setblock ~59~7~67 ice
setblock ~59~7~67 ice 0
setblock ~60~7~67 ice
setblock ~60~7~67 ice 0
setblock ~61~7~67 ice
setblock ~61~7~67 ice 0
setblock ~62~7~67 ice
setblock ~62~7~67 ice 0
setblock ~63~7~67 ice
setblock ~63~7~67 ice 0
setblock ~53~7~68 ice
setblock ~53~7~68 ice 0
setblock ~54~7~68 ice
setblock ~54~7~68 ice 0
setblock ~55~7~68 ice
setblock ~55~7~68 ice 0
setblock ~56~7~68 ice
setblock ~56~7~68 ice 0
setblock ~57~7~68 ice
setblock ~57~7~68 ice 0
setblock ~58~7~68 ice
setblock ~58~7~68 ice 0
setblock ~59~7~68 ice
setblock ~59~7~68 ice 0
setblock ~60~7~68 ice
setblock ~60~7~68 ice 0
setblock ~61~7~68 ice
setblock ~61~7~68 ice 0
setblock ~62~7~68 ice
setblock ~62~7~68 ice 0
setblock ~63~7~68 ice
setblock ~63~7~68 ice 0
setblock ~64~7~68 ice
setblock ~64~7~68 ice 0
setblock ~57~7~69 ice
setblock ~57~7~69 ice 0
setblock ~58~7~69 ice
setblock ~58~7~69 ice 0
setblock ~59~7~69 ice
setblock ~59~7~69 ice 0
setblock ~60~7~69 ice
setblock ~60~7~69 ice 0
setblock ~61~7~69 ice
setblock ~61~7~69 ice 0
setblock ~62~7~69 ice
setblock ~62~7~69 ice 0
setblock ~63~7~69 ice
setblock ~63~7~69 ice 0
setblock ~57~7~70 ice
setblock ~57~7~70 ice 0
setblock ~58~7~70 ice
setblock ~58~7~70 ice 0
setblock ~59~7~70 ice
setblock ~59~7~70 ice 0
setblock ~60~7~70 ice
setblock ~60~7~70 ice 0
setblock ~61~7~70 ice
setblock ~61~7~70 ice 0
setblock ~62~7~70 ice
setblock ~62~7~70 ice 0
setblock ~57~7~71 ice
setblock ~57~7~71 ice 0
setblock ~58~7~71 ice
setblock ~58~7~71 ice 0
setblock ~59~7~71 ice
setblock ~59~7~71 ice 0
setblock ~60~7~71 ice
setblock ~60~7~71 ice 0
setblock ~61~7~71 ice
setblock ~61~7~71 ice 0
setblock ~62~7~71 ice
setblock ~62~7~71 ice 0
setblock ~58~7~72 ice
setblock ~58~7~72 ice 0
setblock ~59~7~72 ice
setblock ~59~7~72 ice 0
setblock ~60~7~72 ice
setblock ~60~7~72 ice 0
setblock ~61~7~72 ice
setblock ~61~7~72 ice 0
setblock ~62~7~72 ice
setblock ~62~7~72 ice 0
setblock ~60~7~73 ice
setblock ~60~7~73 ice 0
setblock ~61~7~73 ice
setblock ~61~7~73 ice 0
setblock ~62~7~73 ice
setblock ~62~7~73 ice 0
setblock ~42~7~81 ice
setblock ~42~7~81 ice 0
setblock ~43~7~81 ice
setblock ~43~7~81 ice 0
setblock ~44~7~81 ice
setblock ~44~7~81 ice 0
setblock ~42~7~82 ice
setblock ~42~7~82 ice 0
setblock ~43~7~82 ice
setblock ~43~7~82 ice 0
setblock ~44~7~82 ice
setblock ~44~7~82 ice 0
setblock ~45~7~82 ice
setblock ~45~7~82 ice 0
setblock ~6~7~83 ice
setblock ~6~7~83 ice 0
setblock ~7~7~83 ice
setblock ~7~7~83 ice 0
setblock ~8~7~83 ice
setblock ~8~7~83 ice 0
setblock ~42~7~83 ice
setblock ~42~7~83 ice 0
setblock ~43~7~83 ice
setblock ~43~7~83 ice 0
setblock ~44~7~83 ice
setblock ~44~7~83 ice 0
setblock ~45~7~83 ice
setblock ~45~7~83 ice 0
setblock ~46~7~83 ice
setblock ~46~7~83 ice 0
setblock ~47~7~83 ice
setblock ~47~7~83 ice 0
setblock ~5~7~84 ice
setblock ~5~7~84 ice 0
setblock ~6~7~84 ice
setblock ~6~7~84 ice 0
setblock ~7~7~84 ice
setblock ~7~7~84 ice 0
setblock ~8~7~84 ice
setblock ~8~7~84 ice 0
setblock ~38~7~84 ice
setblock ~38~7~84 ice 0
setblock ~39~7~84 ice
setblock ~39~7~84 ice 0
setblock ~40~7~84 ice
setblock ~40~7~84 ice 0
setblock ~41~7~84 ice
setblock ~41~7~84 ice 0
setblock ~42~7~84 ice
setblock ~42~7~84 ice 0
setblock ~43~7~84 ice
setblock ~43~7~84 ice 0
setblock ~44~7~84 ice
setblock ~44~7~84 ice 0
setblock ~45~7~84 ice
setblock ~45~7~84 ice 0
setblock ~46~7~84 ice
setblock ~46~7~84 ice 0
setblock ~47~7~84 ice
setblock ~47~7~84 ice 0
setblock ~48~7~84 ice
setblock ~48~7~84 ice 0
setblock ~5~7~85 ice
setblock ~5~7~85 ice 0
setblock ~6~7~85 ice
setblock ~6~7~85 ice 0
setblock ~7~7~85 ice
setblock ~7~7~85 ice 0
setblock ~8~7~85 ice
setblock ~8~7~85 ice 0
setblock ~38~7~85 ice
setblock ~38~7~85 ice 0
setblock ~39~7~85 ice
setblock ~39~7~85 ice 0
setblock ~40~7~85 ice
setblock ~40~7~85 ice 0
setblock ~41~7~85 ice
setblock ~41~7~85 ice 0
setblock ~42~7~85 ice
setblock ~42~7~85 ice 0
setblock ~43~7~85 ice
setblock ~43~7~85 ice 0
setblock ~44~7~85 ice
setblock ~44~7~85 ice 0
setblock ~45~7~85 ice
setblock ~45~7~85 ice 0
setblock ~46~7~85 ice
setblock ~46~7~85 ice 0
setblock ~47~7~85 ice
setblock ~47~7~85 ice 0
setblock ~5~7~86 ice
setblock ~5~7~86 ice 0
setblock ~6~7~86 ice
setblock ~6~7~86 ice 0
setblock ~7~7~86 ice
setblock ~7~7~86 ice 0
setblock ~38~7~86 ice
setblock ~38~7~86 ice 0
setblock ~39~7~86 ice
setblock ~39~7~86 ice 0
setblock ~40~7~86 ice
setblock ~40~7~86 ice 0
setblock ~41~7~86 ice
setblock ~41~7~86 ice 0
setblock ~42~7~86 ice
setblock ~42~7~86 ice 0
setblock ~43~7~86 ice
setblock ~43~7~86 ice 0
setblock ~44~7~86 ice
setblock ~44~7~86 ice 0
setblock ~45~7~86 ice
setblock ~45~7~86 ice 0
setblock ~46~7~86 ice
setblock ~46~7~86 ice 0
setblock ~47~7~86 ice
setblock ~47~7~86 ice 0
setblock ~39~7~87 ice
setblock ~39~7~87 ice 0
setblock ~40~7~87 ice
setblock ~40~7~87 ice 0
setblock ~41~7~87 ice
setblock ~41~7~87 ice 0
setblock ~42~7~87 ice
setblock ~42~7~87 ice 0
setblock ~43~7~87 ice
setblock ~43~7~87 ice 0
setblock ~39~7~88 ice
setblock ~39~7~88 ice 0
setblock ~40~7~88 ice
setblock ~40~7~88 ice 0
setblock ~41~7~88 ice
setblock ~41~7~88 ice 0
setblock ~42~7~88 ice
setblock ~42~7~88 ice 0
setblock ~43~7~88 ice
setblock ~43~7~88 ice 0
setblock ~40~7~89 ice
setblock ~40~7~89 ice 0
setblock ~41~7~89 ice
setblock ~41~7~89 ice 0
setblock ~42~7~89 ice
setblock ~42~7~89 ice 0
setblock ~28~7~107 monster_egg
setblock ~28~7~107 monster_egg 0
setblock ~29~7~107 monster_egg
setblock ~29~7~107 monster_egg 0
setblock ~30~7~107 monster_egg
setblock ~30~7~107 monster_egg 0
setblock ~27~7~108 monster_egg
setblock ~27~7~108 monster_egg 0
setblock ~28~7~108 monster_egg
setblock ~28~7~108 monster_egg 0
setblock ~29~7~108 monster_egg
setblock ~29~7~108 monster_egg 0
setblock ~30~7~108 monster_egg
setblock ~30~7~108 monster_egg 0
setblock ~31~7~108 monster_egg
setblock ~31~7~108 monster_egg 0
setblock ~27~7~109 monster_egg
setblock ~27~7~109 monster_egg 0
setblock ~28~7~109 monster_egg
setblock ~28~7~109 monster_egg 0
setblock ~29~7~109 stained_glass
setblock ~29~7~109 stained_glass 0
setblock ~30~7~109 monster_egg
setblock ~30~7~109 monster_egg 0
setblock ~31~7~109 monster_egg
setblock ~31~7~109 monster_egg 0
setblock ~28~7~110 monster_egg
setblock ~28~7~110 monster_egg 0
setblock ~29~7~110 monster_egg
setblock ~29~7~110 monster_egg 0
setblock ~30~7~110 monster_egg
setblock ~30~7~110 monster_egg 0
setblock ~26~8~15 ice
setblock ~26~8~15 ice 0
setblock ~27~8~15 ice
setblock ~27~8~15 ice 0
setblock ~25~8~16 ice
setblock ~25~8~16 ice 0
setblock ~26~8~16 ice
setblock ~26~8~16 ice 0
setblock ~27~8~16 ice
setblock ~27~8~16 ice 0
setblock ~28~8~16 ice
setblock ~28~8~16 ice 0
setblock ~25~8~17 ice
setblock ~25~8~17 ice 0
setblock ~26~8~17 ice
setblock ~26~8~17 ice 0
setblock ~27~8~17 ice
setblock ~27~8~17 ice 0
setblock ~28~8~17 ice
setblock ~28~8~17 ice 0
setblock ~29~8~17 ice
setblock ~29~8~17 ice 0
setblock ~25~8~18 ice
setblock ~25~8~18 ice 0
setblock ~26~8~18 ice
setblock ~26~8~18 ice 0
setblock ~27~8~18 ice
setblock ~27~8~18 ice 0
setblock ~28~8~18 ice
setblock ~28~8~18 ice 0
setblock ~29~8~18 ice
setblock ~29~8~18 ice 0
setblock ~24~8~19 ice
setblock ~24~8~19 ice 0
setblock ~25~8~19 ice
setblock ~25~8~19 ice 0
setblock ~26~8~19 ice
setblock ~26~8~19 ice 0
setblock ~27~8~19 ice
setblock ~27~8~19 ice 0
setblock ~28~8~19 ice
setblock ~28~8~19 ice 0
setblock ~29~8~19 ice
setblock ~29~8~19 ice 0
setblock ~30~8~19 ice
setblock ~30~8~19 ice 0
setblock ~31~8~19 ice
setblock ~31~8~19 ice 0
setblock ~32~8~19 ice
setblock ~32~8~19 ice 0
setblock ~33~8~19 ice
setblock ~33~8~19 ice 0
setblock ~23~8~20 ice
setblock ~23~8~20 ice 0
setblock ~24~8~20 ice
setblock ~24~8~20 ice 0
setblock ~25~8~20 ice
setblock ~25~8~20 ice 0
setblock ~26~8~20 ice
setblock ~26~8~20 ice 0
setblock ~27~8~20 ice
setblock ~27~8~20 ice 0
setblock ~28~8~20 ice
setblock ~28~8~20 ice 0
setblock ~29~8~20 ice
setblock ~29~8~20 ice 0
setblock ~30~8~20 ice
setblock ~30~8~20 ice 0
setblock ~31~8~20 ice
setblock ~31~8~20 ice 0
setblock ~32~8~20 ice
setblock ~32~8~20 ice 0
setblock ~33~8~20 ice
setblock ~33~8~20 ice 0
setblock ~23~8~21 ice
setblock ~23~8~21 ice 0
setblock ~24~8~21 ice
setblock ~24~8~21 ice 0
setblock ~25~8~21 ice
setblock ~25~8~21 ice 0
setblock ~26~8~21 ice
setblock ~26~8~21 ice 0
setblock ~27~8~21 ice
setblock ~27~8~21 ice 0
setblock ~28~8~21 ice
setblock ~28~8~21 ice 0
setblock ~29~8~21 ice
setblock ~29~8~21 ice 0
setblock ~30~8~21 ice
setblock ~30~8~21 ice 0
setblock ~31~8~21 ice
setblock ~31~8~21 ice 0
setblock ~32~8~21 ice
setblock ~32~8~21 ice 0
setblock ~33~8~21 ice
setblock ~33~8~21 ice 0
setblock ~23~8~22 ice
setblock ~23~8~22 ice 0
setblock ~24~8~22 ice
setblock ~24~8~22 ice 0
setblock ~25~8~22 ice
setblock ~25~8~22 ice 0
setblock ~26~8~22 ice
setblock ~26~8~22 ice 0
setblock ~27~8~22 ice
setblock ~27~8~22 ice 0
setblock ~28~8~22 ice
setblock ~28~8~22 ice 0
setblock ~29~8~22 ice
setblock ~29~8~22 ice 0
setblock ~30~8~22 ice
setblock ~30~8~22 ice 0
setblock ~31~8~22 ice
setblock ~31~8~22 ice 0
setblock ~24~8~23 ice
setblock ~24~8~23 ice 0
setblock ~25~8~23 ice
setblock ~25~8~23 ice 0
setblock ~26~8~23 ice
setblock ~26~8~23 ice 0
setblock ~27~8~23 ice
setblock ~27~8~23 ice 0
setblock ~28~8~23 ice
setblock ~28~8~23 ice 0
setblock ~29~8~23 ice
setblock ~29~8~23 ice 0
setblock ~30~8~23 ice
setblock ~30~8~23 ice 0
setblock ~26~8~24 ice
setblock ~26~8~24 ice 0
setblock ~27~8~24 ice
setblock ~27~8~24 ice 0
setblock ~28~8~24 ice
setblock ~28~8~24 ice 0
setblock ~26~8~25 ice
setblock ~26~8~25 ice 0
setblock ~27~8~25 ice
setblock ~27~8~25 ice 0
setblock ~28~8~25 ice
setblock ~28~8~25 ice 0
setblock ~15~8~43 ice
setblock ~15~8~43 ice 0
setblock ~72~8~43 ice
setblock ~72~8~43 ice 0
setblock ~8~8~44 ice
setblock ~8~8~44 ice 0
setblock ~9~8~44 ice
setblock ~9~8~44 ice 0
setblock ~10~8~44 ice
setblock ~10~8~44 ice 0
setblock ~14~8~44 ice
setblock ~14~8~44 ice 0
setblock ~15~8~44 ice
setblock ~15~8~44 ice 0
setblock ~16~8~44 ice
setblock ~16~8~44 ice 0
setblock ~71~8~44 ice
setblock ~71~8~44 ice 0
setblock ~72~8~44 ice
setblock ~72~8~44 ice 0
setblock ~73~8~44 ice
setblock ~73~8~44 ice 0
setblock ~7~8~45 ice
setblock ~7~8~45 ice 0
setblock ~8~8~45 ice
setblock ~8~8~45 ice 0
setblock ~9~8~45 ice
setblock ~9~8~45 ice 0
setblock ~10~8~45 ice
setblock ~10~8~45 ice 0
setblock ~11~8~45 ice
setblock ~11~8~45 ice 0
setblock ~13~8~45 ice
setblock ~13~8~45 ice 0
setblock ~14~8~45 ice
setblock ~14~8~45 ice 0
setblock ~15~8~45 ice
setblock ~15~8~45 ice 0
setblock ~72~8~45 ice
setblock ~72~8~45 ice 0
setblock ~7~8~46 ice
setblock ~7~8~46 ice 0
setblock ~8~8~46 ice
setblock ~8~8~46 ice 0
setblock ~9~8~46 ice
setblock ~9~8~46 ice 0
setblock ~10~8~46 ice
setblock ~10~8~46 ice 0
setblock ~11~8~46 ice
setblock ~11~8~46 ice 0
setblock ~12~8~46 ice
setblock ~12~8~46 ice 0
setblock ~13~8~46 ice
setblock ~13~8~46 ice 0
setblock ~14~8~46 ice
setblock ~14~8~46 ice 0
setblock ~15~8~46 ice
setblock ~15~8~46 ice 0
setblock ~16~8~46 ice
setblock ~16~8~46 ice 0
setblock ~7~8~47 ice
setblock ~7~8~47 ice 0
setblock ~8~8~47 ice
setblock ~8~8~47 ice 0
setblock ~9~8~47 ice
setblock ~9~8~47 ice 0
setblock ~10~8~47 ice
setblock ~10~8~47 ice 0
setblock ~11~8~47 ice
setblock ~11~8~47 ice 0
setblock ~12~8~47 ice
setblock ~12~8~47 ice 0
setblock ~13~8~47 ice
setblock ~13~8~47 ice 0
setblock ~14~8~47 ice
setblock ~14~8~47 ice 0
setblock ~15~8~47 ice
setblock ~15~8~47 ice 0
setblock ~16~8~47 ice
setblock ~16~8~47 ice 0
setblock ~6~8~48 ice
setblock ~6~8~48 ice 0
setblock ~7~8~48 ice
setblock ~7~8~48 ice 0
setblock ~8~8~48 ice
setblock ~8~8~48 ice 0
setblock ~9~8~48 ice
setblock ~9~8~48 ice 0
setblock ~10~8~48 ice
setblock ~10~8~48 ice 0
setblock ~11~8~48 ice
setblock ~11~8~48 ice 0
setblock ~12~8~48 ice
setblock ~12~8~48 ice 0
setblock ~13~8~48 ice
setblock ~13~8~48 ice 0
setblock ~14~8~48 ice
setblock ~14~8~48 ice 0
setblock ~15~8~48 ice
setblock ~15~8~48 ice 0
setblock ~16~8~48 ice
setblock ~16~8~48 ice 0
setblock ~72~8~48 ice
setblock ~72~8~48 ice 0
setblock ~6~8~49 ice
setblock ~6~8~49 ice 0
setblock ~7~8~49 ice
setblock ~7~8~49 ice 0
setblock ~8~8~49 ice
setblock ~8~8~49 ice 0
setblock ~9~8~49 ice
setblock ~9~8~49 ice 0
setblock ~10~8~49 ice
setblock ~10~8~49 ice 0
setblock ~11~8~49 ice
setblock ~11~8~49 ice 0
setblock ~13~8~49 ice
setblock ~13~8~49 ice 0
setblock ~14~8~49 ice
setblock ~14~8~49 ice 0
setblock ~15~8~49 ice
setblock ~15~8~49 ice 0
setblock ~71~8~49 ice
setblock ~71~8~49 ice 0
setblock ~72~8~49 ice
setblock ~72~8~49 ice 0
setblock ~73~8~49 ice
setblock ~73~8~49 ice 0
setblock ~6~8~50 ice
setblock ~6~8~50 ice 0
setblock ~7~8~50 ice
setblock ~7~8~50 ice 0
setblock ~8~8~50 ice
setblock ~8~8~50 ice 0
setblock ~9~8~50 ice
setblock ~9~8~50 ice 0
setblock ~10~8~50 ice
setblock ~10~8~50 ice 0
setblock ~60~8~50 ice
setblock ~60~8~50 ice 0
setblock ~61~8~50 ice
setblock ~61~8~50 ice 0
setblock ~62~8~50 ice
setblock ~62~8~50 ice 0
setblock ~72~8~50 ice
setblock ~72~8~50 ice 0
setblock ~60~8~51 ice
setblock ~60~8~51 ice 0
setblock ~61~8~51 ice
setblock ~61~8~51 ice 0
setblock ~62~8~51 ice
setblock ~62~8~51 ice 0
setblock ~60~8~52 ice
setblock ~60~8~52 ice 0
setblock ~61~8~52 ice
setblock ~61~8~52 ice 0
setblock ~62~8~52 ice
setblock ~62~8~52 ice 0
setblock ~58~8~59 ice
setblock ~58~8~59 ice 0
setblock ~59~8~59 ice
setblock ~59~8~59 ice 0
setblock ~60~8~59 ice
setblock ~60~8~59 ice 0
setblock ~57~8~60 ice
setblock ~57~8~60 ice 0
setblock ~58~8~60 ice
setblock ~58~8~60 ice 0
setblock ~59~8~60 ice
setblock ~59~8~60 ice 0
setblock ~60~8~60 ice
setblock ~60~8~60 ice 0
setblock ~61~8~60 ice
setblock ~61~8~60 ice 0
setblock ~53~8~61 ice
setblock ~53~8~61 ice 0
setblock ~54~8~61 ice
setblock ~54~8~61 ice 0
setblock ~55~8~61 ice
setblock ~55~8~61 ice 0
setblock ~56~8~61 ice
setblock ~56~8~61 ice 0
setblock ~57~8~61 ice
setblock ~57~8~61 ice 0
setblock ~58~8~61 ice
setblock ~58~8~61 ice 0
setblock ~59~8~61 ice
setblock ~59~8~61 ice 0
setblock ~60~8~61 ice
setblock ~60~8~61 ice 0
setblock ~61~8~61 ice
setblock ~61~8~61 ice 0
setblock ~53~8~62 ice
setblock ~53~8~62 ice 0
setblock ~54~8~62 ice
setblock ~54~8~62 ice 0
setblock ~55~8~62 ice
setblock ~55~8~62 ice 0
setblock ~56~8~62 ice
setblock ~56~8~62 ice 0
setblock ~57~8~62 ice
setblock ~57~8~62 ice 0
setblock ~58~8~62 ice
setblock ~58~8~62 ice 0
setblock ~59~8~62 ice
setblock ~59~8~62 ice 0
setblock ~60~8~62 ice
setblock ~60~8~62 ice 0
setblock ~61~8~62 ice
setblock ~61~8~62 ice 0
setblock ~62~8~62 ice
setblock ~62~8~62 ice 0
setblock ~63~8~62 ice
setblock ~63~8~62 ice 0
setblock ~64~8~62 ice
setblock ~64~8~62 ice 0
setblock ~53~8~63 ice
setblock ~53~8~63 ice 0
setblock ~54~8~63 ice
setblock ~54~8~63 ice 0
setblock ~55~8~63 ice
setblock ~55~8~63 ice 0
setblock ~56~8~63 ice
setblock ~56~8~63 ice 0
setblock ~57~8~63 ice
setblock ~57~8~63 ice 0
setblock ~58~8~63 ice
setblock ~58~8~63 ice 0
setblock ~59~8~63 ice
setblock ~59~8~63 ice 0
setblock ~60~8~63 ice
setblock ~60~8~63 ice 0
setblock ~61~8~63 ice
setblock ~61~8~63 ice 0
setblock ~62~8~63 ice
setblock ~62~8~63 ice 0
setblock ~63~8~63 ice
setblock ~63~8~63 ice 0
setblock ~64~8~63 ice
setblock ~64~8~63 ice 0
setblock ~53~8~64 ice
setblock ~53~8~64 ice 0
setblock ~54~8~64 ice
setblock ~54~8~64 ice 0
setblock ~55~8~64 ice
setblock ~55~8~64 ice 0
setblock ~56~8~64 ice
setblock ~56~8~64 ice 0
setblock ~57~8~64 ice
setblock ~57~8~64 ice 0
setblock ~58~8~64 ice
setblock ~58~8~64 ice 0
setblock ~59~8~64 ice
setblock ~59~8~64 ice 0
setblock ~60~8~64 ice
setblock ~60~8~64 ice 0
setblock ~61~8~64 ice
setblock ~61~8~64 ice 0
setblock ~62~8~64 ice
setblock ~62~8~64 ice 0
setblock ~63~8~64 ice
setblock ~63~8~64 ice 0
setblock ~64~8~64 ice
setblock ~64~8~64 ice 0
setblock ~53~8~65 ice
setblock ~53~8~65 ice 0
setblock ~54~8~65 ice
setblock ~54~8~65 ice 0
setblock ~55~8~65 ice
setblock ~55~8~65 ice 0
setblock ~56~8~65 ice
setblock ~56~8~65 ice 0
setblock ~57~8~65 ice
setblock ~57~8~65 ice 0
setblock ~58~8~65 ice
setblock ~58~8~65 ice 0
setblock ~59~8~65 ice
setblock ~59~8~65 ice 0
setblock ~60~8~65 ice
setblock ~60~8~65 ice 0
setblock ~61~8~65 ice
setblock ~61~8~65 ice 0
setblock ~62~8~65 ice
setblock ~62~8~65 ice 0
setblock ~63~8~65 ice
setblock ~63~8~65 ice 0
setblock ~64~8~65 ice
setblock ~64~8~65 ice 0
setblock ~53~8~66 ice
setblock ~53~8~66 ice 0
setblock ~54~8~66 ice
setblock ~54~8~66 ice 0
setblock ~55~8~66 ice
setblock ~55~8~66 ice 0
setblock ~56~8~66 ice
setblock ~56~8~66 ice 0
setblock ~57~8~66 ice
setblock ~57~8~66 ice 0
setblock ~58~8~66 ice
setblock ~58~8~66 ice 0
setblock ~59~8~66 ice
setblock ~59~8~66 ice 0
setblock ~60~8~66 ice
setblock ~60~8~66 ice 0
setblock ~61~8~66 ice
setblock ~61~8~66 ice 0
setblock ~62~8~66 ice
setblock ~62~8~66 ice 0
setblock ~63~8~66 ice
setblock ~63~8~66 ice 0
setblock ~53~8~67 ice
setblock ~53~8~67 ice 0
setblock ~54~8~67 ice
setblock ~54~8~67 ice 0
setblock ~55~8~67 ice
setblock ~55~8~67 ice 0
setblock ~56~8~67 ice
setblock ~56~8~67 ice 0
setblock ~57~8~67 ice
setblock ~57~8~67 ice 0
setblock ~58~8~67 ice
setblock ~58~8~67 ice 0
setblock ~59~8~67 ice
setblock ~59~8~67 ice 0
setblock ~60~8~67 ice
setblock ~60~8~67 ice 0
setblock ~61~8~67 ice
setblock ~61~8~67 ice 0
setblock ~62~8~67 ice
setblock ~62~8~67 ice 0
setblock ~63~8~67 ice
setblock ~63~8~67 ice 0
setblock ~54~8~68 ice
setblock ~54~8~68 ice 0
setblock ~56~8~68 ice
setblock ~56~8~68 ice 0
setblock ~57~8~68 ice
setblock ~57~8~68 ice 0
setblock ~58~8~68 ice
setblock ~58~8~68 ice 0
setblock ~59~8~68 ice
setblock ~59~8~68 ice 0
setblock ~60~8~68 ice
setblock ~60~8~68 ice 0
setblock ~61~8~68 ice
setblock ~61~8~68 ice 0
setblock ~62~8~68 ice
setblock ~62~8~68 ice 0
setblock ~56~8~69 ice
setblock ~56~8~69 ice 0
setblock ~57~8~69 ice
setblock ~57~8~69 ice 0
setblock ~58~8~69 ice
setblock ~58~8~69 ice 0
setblock ~59~8~69 ice
setblock ~59~8~69 ice 0
setblock ~60~8~69 ice
setblock ~60~8~69 ice 0
setblock ~61~8~69 ice
setblock ~61~8~69 ice 0
setblock ~62~8~69 ice
setblock ~62~8~69 ice 0
setblock ~56~8~70 ice
setblock ~56~8~70 ice 0
setblock ~57~8~70 ice
setblock ~57~8~70 ice 0
setblock ~58~8~70 ice
setblock ~58~8~70 ice 0
setblock ~59~8~70 ice
setblock ~59~8~70 ice 0
setblock ~60~8~70 ice
setblock ~60~8~70 ice 0
setblock ~61~8~70 ice
setblock ~61~8~70 ice 0
setblock ~55~8~71 ice
setblock ~55~8~71 ice 0
setblock ~56~8~71 ice
setblock ~56~8~71 ice 0
setblock ~57~8~71 ice
setblock ~57~8~71 ice 0
setblock ~58~8~71 ice
setblock ~58~8~71 ice 0
setblock ~59~8~71 ice
setblock ~59~8~71 ice 0
setblock ~60~8~71 ice
setblock ~60~8~71 ice 0
setblock ~61~8~71 ice
setblock ~61~8~71 ice 0
setblock ~56~8~72 ice
setblock ~56~8~72 ice 0
setblock ~57~8~72 ice
setblock ~57~8~72 ice 0
setblock ~58~8~72 ice
setblock ~58~8~72 ice 0
setblock ~59~8~72 ice
setblock ~59~8~72 ice 0
setblock ~60~8~72 ice
setblock ~60~8~72 ice 0
setblock ~61~8~72 ice
setblock ~61~8~72 ice 0
setblock ~62~8~72 ice
setblock ~62~8~72 ice 0
setblock ~56~8~73 ice
setblock ~56~8~73 ice 0
setblock ~57~8~73 ice
setblock ~57~8~73 ice 0
setblock ~58~8~73 ice
setblock ~58~8~73 ice 0
setblock ~61~8~73 ice
setblock ~61~8~73 ice 0
setblock ~56~8~74 ice
setblock ~56~8~74 ice 0
setblock ~57~8~74 ice
setblock ~57~8~74 ice 0
setblock ~58~8~74 ice
setblock ~58~8~74 ice 0
setblock ~57~8~75 ice
setblock ~57~8~75 ice 0
setblock ~43~8~81 ice
setblock ~43~8~81 ice 0
setblock ~4~8~82 ice
setblock ~4~8~82 ice 0
setblock ~5~8~82 ice
setblock ~5~8~82 ice 0
setblock ~6~8~82 ice
setblock ~6~8~82 ice 0
setblock ~7~8~82 ice
setblock ~7~8~82 ice 0
setblock ~8~8~82 ice
setblock ~8~8~82 ice 0
setblock ~9~8~82 ice
setblock ~9~8~82 ice 0
setblock ~10~8~82 ice
setblock ~10~8~82 ice 0
setblock ~39~8~82 ice
setblock ~39~8~82 ice 0
setblock ~40~8~82 ice
setblock ~40~8~82 ice 0
setblock ~41~8~82 ice
setblock ~41~8~82 ice 0
setblock ~42~8~82 ice
setblock ~42~8~82 ice 0
setblock ~43~8~82 ice
setblock ~43~8~82 ice 0
setblock ~44~8~82 ice
setblock ~44~8~82 ice 0
setblock ~45~8~82 ice
setblock ~45~8~82 ice 0
setblock ~4~8~83 ice
setblock ~4~8~83 ice 0
setblock ~5~8~83 ice
setblock ~5~8~83 ice 0
setblock ~6~8~83 ice
setblock ~6~8~83 ice 0
setblock ~7~8~83 ice
setblock ~7~8~83 ice 0
setblock ~8~8~83 ice
setblock ~8~8~83 ice 0
setblock ~9~8~83 ice
setblock ~9~8~83 ice 0
setblock ~10~8~83 ice
setblock ~10~8~83 ice 0
setblock ~38~8~83 ice
setblock ~38~8~83 ice 0
setblock ~39~8~83 ice
setblock ~39~8~83 ice 0
setblock ~40~8~83 ice
setblock ~40~8~83 ice 0
setblock ~41~8~83 ice
setblock ~41~8~83 ice 0
setblock ~42~8~83 ice
setblock ~42~8~83 ice 0
setblock ~43~8~83 ice
setblock ~43~8~83 ice 0
setblock ~44~8~83 ice
setblock ~44~8~83 ice 0
setblock ~45~8~83 ice
setblock ~45~8~83 ice 0
setblock ~46~8~83 ice
setblock ~46~8~83 ice 0
setblock ~47~8~83 ice
setblock ~47~8~83 ice 0
setblock ~48~8~83 ice
setblock ~48~8~83 ice 0
setblock ~4~8~84 ice
setblock ~4~8~84 ice 0
setblock ~5~8~84 ice
setblock ~5~8~84 ice 0
setblock ~6~8~84 ice
setblock ~6~8~84 ice 0
setblock ~7~8~84 ice
setblock ~7~8~84 ice 0
setblock ~8~8~84 ice
setblock ~8~8~84 ice 0
setblock ~9~8~84 ice
setblock ~9~8~84 ice 0
setblock ~10~8~84 ice
setblock ~10~8~84 ice 0
setblock ~37~8~84 ice
setblock ~37~8~84 ice 0
setblock ~38~8~84 ice
setblock ~38~8~84 ice 0
setblock ~39~8~84 ice
setblock ~39~8~84 ice 0
setblock ~40~8~84 ice
setblock ~40~8~84 ice 0
setblock ~41~8~84 ice
setblock ~41~8~84 ice 0
setblock ~42~8~84 ice
setblock ~42~8~84 ice 0
setblock ~43~8~84 ice
setblock ~43~8~84 ice 0
setblock ~44~8~84 ice
setblock ~44~8~84 ice 0
setblock ~45~8~84 ice
setblock ~45~8~84 ice 0
setblock ~46~8~84 ice
setblock ~46~8~84 ice 0
setblock ~47~8~84 ice
setblock ~47~8~84 ice 0
setblock ~48~8~84 ice
setblock ~48~8~84 ice 0
setblock ~5~8~85 ice
setblock ~5~8~85 ice 0
setblock ~6~8~85 ice
setblock ~6~8~85 ice 0
setblock ~7~8~85 ice
setblock ~7~8~85 ice 0
setblock ~8~8~85 ice
setblock ~8~8~85 ice 0
setblock ~9~8~85 ice
setblock ~9~8~85 ice 0
setblock ~38~8~85 ice
setblock ~38~8~85 ice 0
setblock ~39~8~85 ice
setblock ~39~8~85 ice 0
setblock ~40~8~85 ice
setblock ~40~8~85 ice 0
setblock ~41~8~85 ice
setblock ~41~8~85 ice 0
setblock ~42~8~85 ice
setblock ~42~8~85 ice 0
setblock ~43~8~85 ice
setblock ~43~8~85 ice 0
setblock ~44~8~85 ice
setblock ~44~8~85 ice 0
setblock ~45~8~85 ice
setblock ~45~8~85 ice 0
setblock ~46~8~85 ice
setblock ~46~8~85 ice 0
setblock ~47~8~85 ice
setblock ~47~8~85 ice 0
setblock ~48~8~85 ice
setblock ~48~8~85 ice 0
setblock ~6~8~86 ice
setblock ~6~8~86 ice 0
setblock ~7~8~86 ice
setblock ~7~8~86 ice 0
setblock ~8~8~86 ice
setblock ~8~8~86 ice 0
setblock ~39~8~86 ice
setblock ~39~8~86 ice 0
setblock ~40~8~86 ice
setblock ~40~8~86 ice 0
setblock ~41~8~86 ice
setblock ~41~8~86 ice 0
setblock ~42~8~86 ice
setblock ~42~8~86 ice 0
setblock ~43~8~86 ice
setblock ~43~8~86 ice 0
setblock ~44~8~86 ice
setblock ~44~8~86 ice 0
setblock ~45~8~86 ice
setblock ~45~8~86 ice 0
setblock ~46~8~86 ice
setblock ~46~8~86 ice 0
setblock ~47~8~86 ice
setblock ~47~8~86 ice 0
setblock ~48~8~86 ice
setblock ~48~8~86 ice 0
setblock ~39~8~87 ice
setblock ~39~8~87 ice 0
setblock ~40~8~87 ice
setblock ~40~8~87 ice 0
setblock ~41~8~87 ice
setblock ~41~8~87 ice 0
setblock ~42~8~87 ice
setblock ~42~8~87 ice 0
setblock ~43~8~87 ice
setblock ~43~8~87 ice 0
setblock ~45~8~87 ice
setblock ~45~8~87 ice 0
setblock ~46~8~87 ice
setblock ~46~8~87 ice 0
setblock ~47~8~87 ice
setblock ~47~8~87 ice 0
setblock ~37~8~88 ice
setblock ~37~8~88 ice 0
setblock ~39~8~88 ice
setblock ~39~8~88 ice 0
setblock ~40~8~88 ice
setblock ~40~8~88 ice 0
setblock ~41~8~88 ice
setblock ~41~8~88 ice 0
setblock ~42~8~88 ice
setblock ~42~8~88 ice 0
setblock ~43~8~88 ice
setblock ~43~8~88 ice 0
setblock ~36~8~89 ice
setblock ~36~8~89 ice 0
setblock ~37~8~89 ice
setblock ~37~8~89 ice 0
setblock ~38~8~89 ice
setblock ~38~8~89 ice 0
setblock ~39~8~89 ice
setblock ~39~8~89 ice 0
setblock ~40~8~89 ice
setblock ~40~8~89 ice 0
setblock ~41~8~89 ice
setblock ~41~8~89 ice 0
setblock ~42~8~89 ice
setblock ~42~8~89 ice 0
setblock ~43~8~89 ice
setblock ~43~8~89 ice 0
setblock ~44~8~89 ice
setblock ~44~8~89 ice 0
setblock ~45~8~89 ice
setblock ~45~8~89 ice 0
setblock ~46~8~89 ice
setblock ~46~8~89 ice 0
setblock ~37~8~90 ice
setblock ~37~8~90 ice 0
setblock ~39~8~90 ice
setblock ~39~8~90 ice 0
setblock ~41~8~90 ice
setblock ~41~8~90 ice 0
setblock ~44~8~90 ice
setblock ~44~8~90 ice 0
setblock ~45~8~90 ice
setblock ~45~8~90 ice 0
setblock ~46~8~90 ice
setblock ~46~8~90 ice 0
setblock ~40~8~91 ice
setblock ~40~8~91 ice 0
setblock ~41~8~91 ice
setblock ~41~8~91 ice 0
setblock ~42~8~91 ice
setblock ~42~8~91 ice 0
setblock ~44~8~91 ice
setblock ~44~8~91 ice 0
setblock ~45~8~91 ice
setblock ~45~8~91 ice 0
setblock ~46~8~91 ice
setblock ~46~8~91 ice 0
setblock ~41~8~92 ice
setblock ~41~8~92 ice 0
setblock ~43~8~92 ice
setblock ~43~8~92 ice 0
setblock ~44~8~92 ice
setblock ~44~8~92 ice 0
setblock ~45~8~92 ice
setblock ~45~8~92 ice 0
setblock ~44~8~93 ice
setblock ~44~8~93 ice 0
setblock ~28~8~107 monster_egg
setblock ~28~8~107 monster_egg 0
setblock ~29~8~107 monster_egg
setblock ~29~8~107 monster_egg 0
setblock ~30~8~107 monster_egg
setblock ~30~8~107 monster_egg 0
setblock ~31~8~107 monster_egg
setblock ~31~8~107 monster_egg 0
setblock ~27~8~108 monster_egg
setblock ~27~8~108 monster_egg 0
setblock ~28~8~108 monster_egg
setblock ~28~8~108 monster_egg 0
setblock ~29~8~108 monster_egg
setblock ~29~8~108 monster_egg 0
setblock ~30~8~108 monster_egg
setblock ~30~8~108 monster_egg 0
setblock ~31~8~108 monster_egg
setblock ~31~8~108 monster_egg 0
setblock ~27~8~109 monster_egg
setblock ~27~8~109 monster_egg 0
setblock ~28~8~109 monster_egg
setblock ~28~8~109 monster_egg 0
setblock ~29~8~109 stained_glass
setblock ~29~8~109 stained_glass 0
setblock ~30~8~109 monster_egg
setblock ~30~8~109 monster_egg 0
setblock ~31~8~109 monster_egg
setblock ~31~8~109 monster_egg 0
setblock ~27~8~110 monster_egg
setblock ~27~8~110 monster_egg 0
setblock ~28~8~110 monster_egg
setblock ~28~8~110 monster_egg 0
setblock ~29~8~110 monster_egg
setblock ~29~8~110 monster_egg 0
setblock ~30~8~110 monster_egg
setblock ~30~8~110 monster_egg 0
setblock ~31~8~110 monster_egg
setblock ~31~8~110 monster_egg 0
setblock ~25~9~15 ice
setblock ~25~9~15 ice 0
setblock ~26~9~15 ice
setblock ~26~9~15 ice 0
setblock ~27~9~15 ice
setblock ~27~9~15 ice 0
setblock ~28~9~15 ice
setblock ~28~9~15 ice 0
setblock ~25~9~16 ice
setblock ~25~9~16 ice 0
setblock ~26~9~16 ice
setblock ~26~9~16 ice 0
setblock ~27~9~16 ice
setblock ~27~9~16 ice 0
setblock ~28~9~16 ice
setblock ~28~9~16 ice 0
setblock ~29~9~16 ice
setblock ~29~9~16 ice 0
setblock ~24~9~17 ice
setblock ~24~9~17 ice 0
setblock ~25~9~17 ice
setblock ~25~9~17 ice 0
setblock ~26~9~17 ice
setblock ~26~9~17 ice 0
setblock ~27~9~17 ice
setblock ~27~9~17 ice 0
setblock ~28~9~17 ice
setblock ~28~9~17 ice 0
setblock ~29~9~17 ice
setblock ~29~9~17 ice 0
setblock ~24~9~18 ice
setblock ~24~9~18 ice 0
setblock ~25~9~18 ice
setblock ~25~9~18 ice 0
setblock ~26~9~18 ice
setblock ~26~9~18 ice 0
setblock ~27~9~18 ice
setblock ~27~9~18 ice 0
setblock ~28~9~18 ice
setblock ~28~9~18 ice 0
setblock ~29~9~18 ice
setblock ~29~9~18 ice 0
setblock ~24~9~19 ice
setblock ~24~9~19 ice 0
setblock ~25~9~19 ice
setblock ~25~9~19 ice 0
setblock ~26~9~19 ice
setblock ~26~9~19 ice 0
setblock ~27~9~19 ice
setblock ~27~9~19 ice 0
setblock ~28~9~19 ice
setblock ~28~9~19 ice 0
setblock ~29~9~19 ice
setblock ~29~9~19 ice 0
setblock ~30~9~19 ice
setblock ~30~9~19 ice 0
setblock ~31~9~19 ice
setblock ~31~9~19 ice 0
setblock ~32~9~19 ice
setblock ~32~9~19 ice 0
setblock ~21~9~20 ice
setblock ~21~9~20 ice 0
setblock ~23~9~20 ice
setblock ~23~9~20 ice 0
setblock ~24~9~20 ice
setblock ~24~9~20 ice 0
setblock ~25~9~20 ice
setblock ~25~9~20 ice 0
setblock ~26~9~20 ice
setblock ~26~9~20 ice 0
setblock ~27~9~20 ice
setblock ~27~9~20 ice 0
setblock ~28~9~20 ice
setblock ~28~9~20 ice 0
setblock ~29~9~20 ice
setblock ~29~9~20 ice 0
setblock ~30~9~20 ice
setblock ~30~9~20 ice 0
setblock ~31~9~20 ice
setblock ~31~9~20 ice 0
setblock ~32~9~20 ice
setblock ~32~9~20 ice 0
setblock ~33~9~20 ice
setblock ~33~9~20 ice 0
setblock ~21~9~21 ice
setblock ~21~9~21 ice 0
setblock ~22~9~21 ice
setblock ~22~9~21 ice 0
setblock ~23~9~21 ice
setblock ~23~9~21 ice 0
setblock ~24~9~21 ice
setblock ~24~9~21 ice 0
setblock ~25~9~21 ice
setblock ~25~9~21 ice 0
setblock ~26~9~21 ice
setblock ~26~9~21 ice 0
setblock ~27~9~21 ice
setblock ~27~9~21 ice 0
setblock ~28~9~21 ice
setblock ~28~9~21 ice 0
setblock ~29~9~21 ice
setblock ~29~9~21 ice 0
setblock ~30~9~21 ice
setblock ~30~9~21 ice 0
setblock ~31~9~21 ice
setblock ~31~9~21 ice 0
setblock ~32~9~21 ice
setblock ~32~9~21 ice 0
setblock ~21~9~22 ice
setblock ~21~9~22 ice 0
setblock ~22~9~22 ice
setblock ~22~9~22 ice 0
setblock ~23~9~22 ice
setblock ~23~9~22 ice 0
setblock ~24~9~22 ice
setblock ~24~9~22 ice 0
setblock ~25~9~22 ice
setblock ~25~9~22 ice 0
setblock ~26~9~22 ice
setblock ~26~9~22 ice 0
setblock ~27~9~22 ice
setblock ~27~9~22 ice 0
setblock ~28~9~22 ice
setblock ~28~9~22 ice 0
setblock ~29~9~22 ice
setblock ~29~9~22 ice 0
setblock ~30~9~22 ice
setblock ~30~9~22 ice 0
setblock ~31~9~22 ice
setblock ~31~9~22 ice 0
setblock ~21~9~23 ice
setblock ~21~9~23 ice 0
setblock ~22~9~23 ice
setblock ~22~9~23 ice 0
setblock ~23~9~23 ice
setblock ~23~9~23 ice 0
setblock ~24~9~23 ice
setblock ~24~9~23 ice 0
setblock ~25~9~23 ice
setblock ~25~9~23 ice 0
setblock ~26~9~23 ice
setblock ~26~9~23 ice 0
setblock ~27~9~23 ice
setblock ~27~9~23 ice 0
setblock ~28~9~23 ice
setblock ~28~9~23 ice 0
setblock ~29~9~23 ice
setblock ~29~9~23 ice 0
setblock ~30~9~23 ice
setblock ~30~9~23 ice 0
setblock ~35~9~23 ice
setblock ~35~9~23 ice 0
setblock ~22~9~24 ice
setblock ~22~9~24 ice 0
setblock ~25~9~24 ice
setblock ~25~9~24 ice 0
setblock ~26~9~24 ice
setblock ~26~9~24 ice 0
setblock ~27~9~24 ice
setblock ~27~9~24 ice 0
setblock ~28~9~24 ice
setblock ~28~9~24 ice 0
setblock ~29~9~24 ice
setblock ~29~9~24 ice 0
setblock ~30~9~24 ice
setblock ~30~9~24 ice 0
setblock ~31~9~24 ice
setblock ~31~9~24 ice 0
setblock ~32~9~24 ice
setblock ~32~9~24 ice 0
setblock ~33~9~24 ice
setblock ~33~9~24 ice 0
setblock ~34~9~24 ice
setblock ~34~9~24 ice 0
setblock ~35~9~24 ice
setblock ~35~9~24 ice 0
setblock ~36~9~24 ice
setblock ~36~9~24 ice 0
setblock ~25~9~25 ice
setblock ~25~9~25 ice 0
setblock ~26~9~25 ice
setblock ~26~9~25 ice 0
setblock ~27~9~25 ice
setblock ~27~9~25 ice 0
setblock ~28~9~25 ice
setblock ~28~9~25 ice 0
setblock ~29~9~25 ice
setblock ~29~9~25 ice 0
setblock ~30~9~25 ice
setblock ~30~9~25 ice 0
setblock ~31~9~25 ice
setblock ~31~9~25 ice 0
setblock ~32~9~25 ice
setblock ~32~9~25 ice 0
setblock ~33~9~25 ice
setblock ~33~9~25 ice 0
setblock ~35~9~25 ice
setblock ~35~9~25 ice 0
setblock ~26~9~26 ice
setblock ~26~9~26 ice 0
setblock ~27~9~26 ice
setblock ~27~9~26 ice 0
setblock ~28~9~26 ice
setblock ~28~9~26 ice 0
setblock ~29~9~26 ice
setblock ~29~9~26 ice 0
setblock ~30~9~26 ice
setblock ~30~9~26 ice 0
setblock ~31~9~26 ice
setblock ~31~9~26 ice 0
setblock ~32~9~26 ice
setblock ~32~9~26 ice 0
setblock ~33~9~26 ice
setblock ~33~9~26 ice 0
setblock ~7~9~43 ice
setblock ~7~9~43 ice 0
setblock ~8~9~43 ice
setblock ~8~9~43 ice 0
setblock ~9~9~43 ice
setblock ~9~9~43 ice 0
setblock ~14~9~43 ice
setblock ~14~9~43 ice 0
setblock ~15~9~43 ice
setblock ~15~9~43 ice 0
setblock ~16~9~43 ice
setblock ~16~9~43 ice 0
setblock ~71~9~43 ice
setblock ~71~9~43 ice 0
setblock ~72~9~43 ice
setblock ~72~9~43 ice 0
setblock ~73~9~43 ice
setblock ~73~9~43 ice 0
setblock ~7~9~44 ice
setblock ~7~9~44 ice 0
setblock ~8~9~44 ice
setblock ~8~9~44 ice 0
setblock ~9~9~44 ice
setblock ~9~9~44 ice 0
setblock ~10~9~44 ice
setblock ~10~9~44 ice 0
setblock ~11~9~44 ice
setblock ~11~9~44 ice 0
setblock ~13~9~44 ice
setblock ~13~9~44 ice 0
setblock ~14~9~44 ice
setblock ~14~9~44 ice 0
setblock ~15~9~44 ice
setblock ~15~9~44 ice 0
setblock ~16~9~44 ice
setblock ~16~9~44 ice 0
setblock ~70~9~44 ice
setblock ~70~9~44 ice 0
setblock ~71~9~44 ice
setblock ~71~9~44 ice 0
setblock ~72~9~44 ice
setblock ~72~9~44 ice 0
setblock ~73~9~44 ice
setblock ~73~9~44 ice 0
setblock ~6~9~45 ice
setblock ~6~9~45 ice 0
setblock ~7~9~45 ice
setblock ~7~9~45 ice 0
setblock ~8~9~45 ice
setblock ~8~9~45 ice 0
setblock ~9~9~45 ice
setblock ~9~9~45 ice 0
setblock ~10~9~45 ice
setblock ~10~9~45 ice 0
setblock ~11~9~45 ice
setblock ~11~9~45 ice 0
setblock ~12~9~45 ice
setblock ~12~9~45 ice 0
setblock ~13~9~45 ice
setblock ~13~9~45 ice 0
setblock ~14~9~45 ice
setblock ~14~9~45 ice 0
setblock ~15~9~45 ice
setblock ~15~9~45 ice 0
setblock ~16~9~45 ice
setblock ~16~9~45 ice 0
setblock ~32~9~45 monster_egg
setblock ~32~9~45 monster_egg 0
setblock ~33~9~45 monster_egg
setblock ~33~9~45 monster_egg 0
setblock ~35~9~45 monster_egg
setblock ~35~9~45 monster_egg 0
setblock ~36~9~45 monster_egg
setblock ~36~9~45 monster_egg 0
setblock ~68~9~45 ice
setblock ~68~9~45 ice 0
setblock ~70~9~45 ice
setblock ~70~9~45 ice 0
setblock ~71~9~45 ice
setblock ~71~9~45 ice 0
setblock ~72~9~45 ice
setblock ~72~9~45 ice 0
setblock ~73~9~45 ice
setblock ~73~9~45 ice 0
setblock ~5~9~46 ice
setblock ~5~9~46 ice 0
setblock ~6~9~46 ice
setblock ~6~9~46 ice 0
setblock ~7~9~46 ice
setblock ~7~9~46 ice 0
setblock ~8~9~46 ice
setblock ~8~9~46 ice 0
setblock ~9~9~46 ice
setblock ~9~9~46 ice 0
setblock ~10~9~46 ice
setblock ~10~9~46 ice 0
setblock ~11~9~46 ice
setblock ~11~9~46 ice 0
setblock ~12~9~46 ice
setblock ~12~9~46 ice 0
setblock ~13~9~46 ice
setblock ~13~9~46 ice 0
setblock ~14~9~46 ice
setblock ~14~9~46 ice 0
setblock ~15~9~46 ice
setblock ~15~9~46 ice 0
setblock ~16~9~46 ice
setblock ~16~9~46 ice 0
setblock ~30~9~46 monster_egg
setblock ~30~9~46 monster_egg 0
setblock ~31~9~46 monster_egg
setblock ~31~9~46 monster_egg 0
setblock ~32~9~46 monster_egg
setblock ~32~9~46 monster_egg 0
setblock ~33~9~46 monster_egg
setblock ~33~9~46 monster_egg 0
setblock ~34~9~46 monster_egg
setblock ~34~9~46 monster_egg 0
setblock ~35~9~46 monster_egg
setblock ~35~9~46 monster_egg 0
setblock ~36~9~46 monster_egg
setblock ~36~9~46 monster_egg 0
setblock ~37~9~46 monster_egg
setblock ~37~9~46 monster_egg 0
setblock ~38~9~46 monster_egg
setblock ~38~9~46 monster_egg 0
setblock ~67~9~46 ice
setblock ~67~9~46 ice 0
setblock ~68~9~46 ice
setblock ~68~9~46 ice 0
setblock ~69~9~46 ice
setblock ~69~9~46 ice 0
setblock ~70~9~46 ice
setblock ~70~9~46 ice 0
setblock ~71~9~46 ice
setblock ~71~9~46 ice 0
setblock ~72~9~46 ice
setblock ~72~9~46 ice 0
setblock ~6~9~47 ice
setblock ~6~9~47 ice 0
setblock ~7~9~47 ice
setblock ~7~9~47 ice 0
setblock ~8~9~47 ice
setblock ~8~9~47 ice 0
setblock ~9~9~47 ice
setblock ~9~9~47 ice 0
setblock ~10~9~47 ice
setblock ~10~9~47 ice 0
setblock ~11~9~47 ice
setblock ~11~9~47 ice 0
setblock ~12~9~47 ice
setblock ~12~9~47 ice 0
setblock ~13~9~47 ice
setblock ~13~9~47 ice 0
setblock ~14~9~47 ice
setblock ~14~9~47 ice 0
setblock ~15~9~47 ice
setblock ~15~9~47 ice 0
setblock ~16~9~47 ice
setblock ~16~9~47 ice 0
setblock ~30~9~47 monster_egg
setblock ~30~9~47 monster_egg 0
setblock ~31~9~47 monster_egg
setblock ~31~9~47 monster_egg 0
setblock ~32~9~47 monster_egg
setblock ~32~9~47 monster_egg 0
setblock ~33~9~47 monster_egg
setblock ~33~9~47 monster_egg 0
setblock ~34~9~47 monster_egg
setblock ~34~9~47 monster_egg 0
setblock ~35~9~47 monster_egg
setblock ~35~9~47 monster_egg 0
setblock ~36~9~47 monster_egg
setblock ~36~9~47 monster_egg 0
setblock ~37~9~47 monster_egg
setblock ~37~9~47 monster_egg 0
setblock ~38~9~47 monster_egg
setblock ~38~9~47 monster_egg 0
setblock ~68~9~47 ice
setblock ~68~9~47 ice 0
setblock ~70~9~47 ice
setblock ~70~9~47 ice 0
setblock ~7~9~48 ice
setblock ~7~9~48 ice 0
setblock ~8~9~48 ice
setblock ~8~9~48 ice 0
setblock ~9~9~48 ice
setblock ~9~9~48 ice 0
setblock ~10~9~48 ice
setblock ~10~9~48 ice 0
setblock ~11~9~48 ice
setblock ~11~9~48 ice 0
setblock ~12~9~48 ice
setblock ~12~9~48 ice 0
setblock ~13~9~48 ice
setblock ~13~9~48 ice 0
setblock ~14~9~48 ice
setblock ~14~9~48 ice 0
setblock ~15~9~48 ice
setblock ~15~9~48 ice 0
setblock ~16~9~48 ice
setblock ~16~9~48 ice 0
setblock ~29~9~48 monster_egg
setblock ~29~9~48 monster_egg 0
setblock ~30~9~48 monster_egg
setblock ~30~9~48 monster_egg 0
setblock ~31~9~48 monster_egg
setblock ~31~9~48 monster_egg 0
setblock ~32~9~48 monster_egg
setblock ~32~9~48 monster_egg 0
setblock ~33~9~48 monster_egg
setblock ~33~9~48 monster_egg 0
setblock ~34~9~48 monster_egg
setblock ~34~9~48 monster_egg 0
setblock ~35~9~48 monster_egg
setblock ~35~9~48 monster_egg 0
setblock ~36~9~48 monster_egg
setblock ~36~9~48 monster_egg 0
setblock ~37~9~48 monster_egg
setblock ~37~9~48 monster_egg 0
setblock ~38~9~48 monster_egg
setblock ~38~9~48 monster_egg 0
setblock ~39~9~48 monster_egg
setblock ~39~9~48 monster_egg 0
setblock ~69~9~48 ice
setblock ~69~9~48 ice 0
setblock ~70~9~48 ice
setblock ~70~9~48 ice 0
setblock ~71~9~48 ice
setblock ~71~9~48 ice 0
setblock ~72~9~48 ice
setblock ~72~9~48 ice 0
setblock ~73~9~48 ice
setblock ~73~9~48 ice 0
setblock ~6~9~49 ice
setblock ~6~9~49 ice 0
setblock ~7~9~49 ice
setblock ~7~9~49 ice 0
setblock ~8~9~49 ice
setblock ~8~9~49 ice 0
setblock ~9~9~49 ice
setblock ~9~9~49 ice 0
setblock ~10~9~49 ice
setblock ~10~9~49 ice 0
setblock ~11~9~49 ice
setblock ~11~9~49 ice 0
setblock ~13~9~49 ice
setblock ~13~9~49 ice 0
setblock ~14~9~49 ice
setblock ~14~9~49 ice 0
setblock ~15~9~49 ice
setblock ~15~9~49 ice 0
setblock ~29~9~49 monster_egg
setblock ~29~9~49 monster_egg 0
setblock ~30~9~49 monster_egg
setblock ~30~9~49 monster_egg 0
setblock ~31~9~49 monster_egg
setblock ~31~9~49 monster_egg 0
setblock ~32~9~49 monster_egg
setblock ~32~9~49 monster_egg 0
setblock ~33~9~49 monster_egg
setblock ~33~9~49 monster_egg 0
setblock ~34~9~49 monster_egg
setblock ~34~9~49 monster_egg 0
setblock ~35~9~49 monster_egg
setblock ~35~9~49 monster_egg 0
setblock ~36~9~49 monster_egg
setblock ~36~9~49 monster_egg 0
setblock ~37~9~49 monster_egg
setblock ~37~9~49 monster_egg 0
setblock ~38~9~49 monster_egg
setblock ~38~9~49 monster_egg 0
setblock ~39~9~49 monster_egg
setblock ~39~9~49 monster_egg 0
setblock ~60~9~49 ice
setblock ~60~9~49 ice 0
setblock ~61~9~49 ice
setblock ~61~9~49 ice 0
setblock ~62~9~49 ice
setblock ~62~9~49 ice 0
setblock ~70~9~49 ice
setblock ~70~9~49 ice 0
setblock ~71~9~49 ice
setblock ~71~9~49 ice 0
setblock ~72~9~49 ice
setblock ~72~9~49 ice 0
setblock ~73~9~49 ice
setblock ~73~9~49 ice 0
setblock ~3~9~50 ice
setblock ~3~9~50 ice 0
setblock ~5~9~50 ice
setblock ~5~9~50 ice 0
setblock ~7~9~50 ice
setblock ~7~9~50 ice 0
setblock ~8~9~50 ice
setblock ~8~9~50 ice 0
setblock ~9~9~50 ice
setblock ~9~9~50 ice 0
setblock ~10~9~50 ice
setblock ~10~9~50 ice 0
setblock ~30~9~50 monster_egg
setblock ~30~9~50 monster_egg 0
setblock ~31~9~50 monster_egg
setblock ~31~9~50 monster_egg 0
setblock ~32~9~50 monster_egg
setblock ~32~9~50 monster_egg 0
setblock ~33~9~50 monster_egg
setblock ~33~9~50 monster_egg 0
setblock ~34~9~50 monster_egg
setblock ~34~9~50 monster_egg 0
setblock ~35~9~50 monster_egg
setblock ~35~9~50 monster_egg 0
setblock ~36~9~50 monster_egg
setblock ~36~9~50 monster_egg 0
setblock ~37~9~50 monster_egg
setblock ~37~9~50 monster_egg 0
setblock ~38~9~50 monster_egg
setblock ~38~9~50 monster_egg 0
setblock ~59~9~50 ice
setblock ~59~9~50 ice 0
setblock ~60~9~50 ice
setblock ~60~9~50 ice 0
setblock ~61~9~50 ice
setblock ~61~9~50 ice 0
setblock ~62~9~50 ice
setblock ~62~9~50 ice 0
setblock ~63~9~50 ice
setblock ~63~9~50 ice 0
setblock ~71~9~50 ice
setblock ~71~9~50 ice 0
setblock ~72~9~50 ice
setblock ~72~9~50 ice 0
setblock ~73~9~50 ice
setblock ~73~9~50 ice 0
setblock ~2~9~51 ice
setblock ~2~9~51 ice 0
setblock ~3~9~51 ice
setblock ~3~9~51 ice 0
setblock ~4~9~51 ice
setblock ~4~9~51 ice 0
setblock ~5~9~51 ice
setblock ~5~9~51 ice 0
setblock ~6~9~51 ice
setblock ~6~9~51 ice 0
setblock ~30~9~51 monster_egg
setblock ~30~9~51 monster_egg 0
setblock ~31~9~51 monster_egg
setblock ~31~9~51 monster_egg 0
setblock ~32~9~51 monster_egg
setblock ~32~9~51 monster_egg 0
setblock ~33~9~51 monster_egg
setblock ~33~9~51 monster_egg 0
setblock ~34~9~51 monster_egg
setblock ~34~9~51 monster_egg 0
setblock ~35~9~51 monster_egg
setblock ~35~9~51 monster_egg 0
setblock ~36~9~51 monster_egg
setblock ~36~9~51 monster_egg 0
setblock ~37~9~51 monster_egg
setblock ~37~9~51 monster_egg 0
setblock ~38~9~51 monster_egg
setblock ~38~9~51 monster_egg 0
setblock ~59~9~51 ice
setblock ~59~9~51 ice 0
setblock ~60~9~51 ice
setblock ~60~9~51 ice 0
setblock ~61~9~51 ice
setblock ~61~9~51 ice 0
setblock ~62~9~51 ice
setblock ~62~9~51 ice 0
setblock ~63~9~51 ice
setblock ~63~9~51 ice 0
setblock ~3~9~52 ice
setblock ~3~9~52 ice 0
setblock ~5~9~52 ice
setblock ~5~9~52 ice 0
setblock ~31~9~52 monster_egg
setblock ~31~9~52 monster_egg 0
setblock ~32~9~52 monster_egg
setblock ~32~9~52 monster_egg 0
setblock ~33~9~52 monster_egg
setblock ~33~9~52 monster_egg 0
setblock ~34~9~52 monster_egg
setblock ~34~9~52 monster_egg 0
setblock ~35~9~52 monster_egg
setblock ~35~9~52 monster_egg 0
setblock ~36~9~52 monster_egg
setblock ~36~9~52 monster_egg 0
setblock ~37~9~52 monster_egg
setblock ~37~9~52 monster_egg 0
setblock ~59~9~52 ice
setblock ~59~9~52 ice 0
setblock ~60~9~52 ice
setblock ~60~9~52 ice 0
setblock ~61~9~52 ice
setblock ~61~9~52 ice 0
setblock ~62~9~52 ice
setblock ~62~9~52 ice 0
setblock ~63~9~52 ice
setblock ~63~9~52 ice 0
setblock ~31~9~53 monster_egg
setblock ~31~9~53 monster_egg 0
setblock ~32~9~53 monster_egg
setblock ~32~9~53 monster_egg 0
setblock ~33~9~53 monster_egg
setblock ~33~9~53 monster_egg 0
setblock ~34~9~53 monster_egg
setblock ~34~9~53 monster_egg 0
setblock ~35~9~53 monster_egg
setblock ~35~9~53 monster_egg 0
setblock ~36~9~53 monster_egg
setblock ~36~9~53 monster_egg 0
setblock ~37~9~53 monster_egg
setblock ~37~9~53 monster_egg 0
setblock ~60~9~53 ice
setblock ~60~9~53 ice 0
setblock ~61~9~53 ice
setblock ~61~9~53 ice 0
setblock ~62~9~53 ice
setblock ~62~9~53 ice 0
setblock ~32~9~54 monster_egg
setblock ~32~9~54 monster_egg 0
setblock ~33~9~54 monster_egg
setblock ~33~9~54 monster_egg 0
setblock ~34~9~54 monster_egg
setblock ~34~9~54 monster_egg 0
setblock ~35~9~54 monster_egg
setblock ~35~9~54 monster_egg 0
setblock ~36~9~54 monster_egg
setblock ~36~9~54 monster_egg 0
setblock ~59~9~59 ice
setblock ~59~9~59 ice 0
setblock ~58~9~60 ice
setblock ~58~9~60 ice 0
setblock ~59~9~60 ice
setblock ~59~9~60 ice 0
setblock ~60~9~60 ice
setblock ~60~9~60 ice 0
setblock ~54~9~61 ice
setblock ~54~9~61 ice 0
setblock ~55~9~61 ice
setblock ~55~9~61 ice 0
setblock ~56~9~61 ice
setblock ~56~9~61 ice 0
setblock ~57~9~61 ice
setblock ~57~9~61 ice 0
setblock ~58~9~61 ice
setblock ~58~9~61 ice 0
setblock ~59~9~61 ice
setblock ~59~9~61 ice 0
setblock ~60~9~61 ice
setblock ~60~9~61 ice 0
setblock ~61~9~61 ice
setblock ~61~9~61 ice 0
setblock ~53~9~62 ice
setblock ~53~9~62 ice 0
setblock ~54~9~62 ice
setblock ~54~9~62 ice 0
setblock ~55~9~62 ice
setblock ~55~9~62 ice 0
setblock ~56~9~62 ice
setblock ~56~9~62 ice 0
setblock ~57~9~62 ice
setblock ~57~9~62 ice 0
setblock ~58~9~62 ice
setblock ~58~9~62 ice 0
setblock ~59~9~62 ice
setblock ~59~9~62 ice 0
setblock ~60~9~62 ice
setblock ~60~9~62 ice 0
setblock ~61~9~62 ice
setblock ~61~9~62 ice 0
setblock ~62~9~62 ice
setblock ~62~9~62 ice 0
setblock ~63~9~62 ice
setblock ~63~9~62 ice 0
setblock ~54~9~63 ice
setblock ~54~9~63 ice 0
setblock ~55~9~63 ice
setblock ~55~9~63 ice 0
setblock ~56~9~63 ice
setblock ~56~9~63 ice 0
setblock ~57~9~63 ice
setblock ~57~9~63 ice 0
setblock ~58~9~63 ice
setblock ~58~9~63 ice 0
setblock ~59~9~63 ice
setblock ~59~9~63 ice 0
setblock ~60~9~63 ice
setblock ~60~9~63 ice 0
setblock ~61~9~63 ice
setblock ~61~9~63 ice 0
setblock ~62~9~63 ice
setblock ~62~9~63 ice 0
setblock ~63~9~63 ice
setblock ~63~9~63 ice 0
setblock ~64~9~63 ice
setblock ~64~9~63 ice 0
setblock ~53~9~64 ice
setblock ~53~9~64 ice 0
setblock ~54~9~64 ice
setblock ~54~9~64 ice 0
setblock ~55~9~64 ice
setblock ~55~9~64 ice 0
setblock ~56~9~64 ice
setblock ~56~9~64 ice 0
setblock ~57~9~64 ice
setblock ~57~9~64 ice 0
setblock ~58~9~64 ice
setblock ~58~9~64 ice 0
setblock ~59~9~64 ice
setblock ~59~9~64 ice 0
setblock ~60~9~64 ice
setblock ~60~9~64 ice 0
setblock ~61~9~64 ice
setblock ~61~9~64 ice 0
setblock ~62~9~64 ice
setblock ~62~9~64 ice 0
setblock ~63~9~64 ice
setblock ~63~9~64 ice 0
setblock ~64~9~64 ice
setblock ~64~9~64 ice 0
setblock ~52~9~65 ice
setblock ~52~9~65 ice 0
setblock ~53~9~65 ice
setblock ~53~9~65 ice 0
setblock ~54~9~65 ice
setblock ~54~9~65 ice 0
setblock ~55~9~65 ice
setblock ~55~9~65 ice 0
setblock ~56~9~65 ice
setblock ~56~9~65 ice 0
setblock ~57~9~65 ice
setblock ~57~9~65 ice 0
setblock ~58~9~65 ice
setblock ~58~9~65 ice 0
setblock ~59~9~65 ice
setblock ~59~9~65 ice 0
setblock ~60~9~65 ice
setblock ~60~9~65 ice 0
setblock ~61~9~65 ice
setblock ~61~9~65 ice 0
setblock ~62~9~65 ice
setblock ~62~9~65 ice 0
setblock ~63~9~65 ice
setblock ~63~9~65 ice 0
setblock ~64~9~65 ice
setblock ~64~9~65 ice 0
setblock ~52~9~66 ice
setblock ~52~9~66 ice 0
setblock ~53~9~66 ice
setblock ~53~9~66 ice 0
setblock ~54~9~66 ice
setblock ~54~9~66 ice 0
setblock ~55~9~66 ice
setblock ~55~9~66 ice 0
setblock ~56~9~66 ice
setblock ~56~9~66 ice 0
setblock ~57~9~66 ice
setblock ~57~9~66 ice 0
setblock ~58~9~66 ice
setblock ~58~9~66 ice 0
setblock ~59~9~66 ice
setblock ~59~9~66 ice 0
setblock ~60~9~66 ice
setblock ~60~9~66 ice 0
setblock ~61~9~66 ice
setblock ~61~9~66 ice 0
setblock ~62~9~66 ice
setblock ~62~9~66 ice 0
setblock ~63~9~66 ice
setblock ~63~9~66 ice 0
setblock ~52~9~67 ice
setblock ~52~9~67 ice 0
setblock ~53~9~67 ice
setblock ~53~9~67 ice 0
setblock ~54~9~67 ice
setblock ~54~9~67 ice 0
setblock ~55~9~67 ice
setblock ~55~9~67 ice 0
setblock ~56~9~67 ice
setblock ~56~9~67 ice 0
setblock ~57~9~67 ice
setblock ~57~9~67 ice 0
setblock ~58~9~67 ice
setblock ~58~9~67 ice 0
setblock ~59~9~67 ice
setblock ~59~9~67 ice 0
setblock ~60~9~67 ice
setblock ~60~9~67 ice 0
setblock ~61~9~67 ice
setblock ~61~9~67 ice 0
setblock ~62~9~67 ice
setblock ~62~9~67 ice 0
setblock ~63~9~67 ice
setblock ~63~9~67 ice 0
setblock ~53~9~68 ice
setblock ~53~9~68 ice 0
setblock ~54~9~68 ice
setblock ~54~9~68 ice 0
setblock ~55~9~68 ice
setblock ~55~9~68 ice 0
setblock ~56~9~68 ice
setblock ~56~9~68 ice 0
setblock ~57~9~68 ice
setblock ~57~9~68 ice 0
setblock ~58~9~68 ice
setblock ~58~9~68 ice 0
setblock ~59~9~68 ice
setblock ~59~9~68 ice 0
setblock ~60~9~68 ice
setblock ~60~9~68 ice 0
setblock ~61~9~68 ice
setblock ~61~9~68 ice 0
setblock ~62~9~68 ice
setblock ~62~9~68 ice 0
setblock ~63~9~68 ice
setblock ~63~9~68 ice 0
setblock ~56~9~69 ice
setblock ~56~9~69 ice 0
setblock ~57~9~69 ice
setblock ~57~9~69 ice 0
setblock ~58~9~69 ice
setblock ~58~9~69 ice 0
setblock ~59~9~69 ice
setblock ~59~9~69 ice 0
setblock ~60~9~69 ice
setblock ~60~9~69 ice 0
setblock ~61~9~69 ice
setblock ~61~9~69 ice 0
setblock ~62~9~69 ice
setblock ~62~9~69 ice 0
setblock ~54~9~70 ice
setblock ~54~9~70 ice 0
setblock ~55~9~70 ice
setblock ~55~9~70 ice 0
setblock ~56~9~70 ice
setblock ~56~9~70 ice 0
setblock ~57~9~70 ice
setblock ~57~9~70 ice 0
setblock ~58~9~70 ice
setblock ~58~9~70 ice 0
setblock ~59~9~70 ice
setblock ~59~9~70 ice 0
setblock ~60~9~70 ice
setblock ~60~9~70 ice 0
setblock ~61~9~70 ice
setblock ~61~9~70 ice 0
setblock ~62~9~70 ice
setblock ~62~9~70 ice 0
setblock ~54~9~71 ice
setblock ~54~9~71 ice 0
setblock ~55~9~71 ice
setblock ~55~9~71 ice 0
setblock ~56~9~71 ice
setblock ~56~9~71 ice 0
setblock ~57~9~71 ice
setblock ~57~9~71 ice 0
setblock ~58~9~71 ice
setblock ~58~9~71 ice 0
setblock ~59~9~71 ice
setblock ~59~9~71 ice 0
setblock ~60~9~71 ice
setblock ~60~9~71 ice 0
setblock ~61~9~71 ice
setblock ~61~9~71 ice 0
setblock ~62~9~71 ice
setblock ~62~9~71 ice 0
setblock ~54~9~72 ice
setblock ~54~9~72 ice 0
setblock ~55~9~72 ice
setblock ~55~9~72 ice 0
setblock ~56~9~72 ice
setblock ~56~9~72 ice 0
setblock ~57~9~72 ice
setblock ~57~9~72 ice 0
setblock ~58~9~72 ice
setblock ~58~9~72 ice 0
setblock ~59~9~72 ice
setblock ~59~9~72 ice 0
setblock ~60~9~72 ice
setblock ~60~9~72 ice 0
setblock ~61~9~72 ice
setblock ~61~9~72 ice 0
setblock ~55~9~73 ice
setblock ~55~9~73 ice 0
setblock ~56~9~73 ice
setblock ~56~9~73 ice 0
setblock ~57~9~73 ice
setblock ~57~9~73 ice 0
setblock ~58~9~73 ice
setblock ~58~9~73 ice 0
setblock ~59~9~73 ice
setblock ~59~9~73 ice 0
setblock ~55~9~74 ice
setblock ~55~9~74 ice 0
setblock ~56~9~74 ice
setblock ~56~9~74 ice 0
setblock ~57~9~74 ice
setblock ~57~9~74 ice 0
setblock ~58~9~74 ice
setblock ~58~9~74 ice 0
setblock ~56~9~75 ice
setblock ~56~9~75 ice 0
setblock ~57~9~75 ice
setblock ~57~9~75 ice 0
setblock ~58~9~75 ice
setblock ~58~9~75 ice 0
setblock ~4~9~81 ice
setblock ~4~9~81 ice 0
setblock ~5~9~81 ice
setblock ~5~9~81 ice 0
setblock ~6~9~81 ice
setblock ~6~9~81 ice 0
setblock ~8~9~81 ice
setblock ~8~9~81 ice 0
setblock ~9~9~81 ice
setblock ~9~9~81 ice 0
setblock ~10~9~81 ice
setblock ~10~9~81 ice 0
setblock ~11~9~81 ice
setblock ~11~9~81 ice 0
setblock ~12~9~81 ice
setblock ~12~9~81 ice 0
setblock ~39~9~81 ice
setblock ~39~9~81 ice 0
setblock ~40~9~81 ice
setblock ~40~9~81 ice 0
setblock ~41~9~81 ice
setblock ~41~9~81 ice 0
setblock ~3~9~82 ice
setblock ~3~9~82 ice 0
setblock ~4~9~82 ice
setblock ~4~9~82 ice 0
setblock ~5~9~82 ice
setblock ~5~9~82 ice 0
setblock ~6~9~82 ice
setblock ~6~9~82 ice 0
setblock ~7~9~82 ice
setblock ~7~9~82 ice 0
setblock ~8~9~82 ice
setblock ~8~9~82 ice 0
setblock ~9~9~82 ice
setblock ~9~9~82 ice 0
setblock ~10~9~82 ice
setblock ~10~9~82 ice 0
setblock ~11~9~82 ice
setblock ~11~9~82 ice 0
setblock ~12~9~82 ice
setblock ~12~9~82 ice 0
setblock ~38~9~82 ice
setblock ~38~9~82 ice 0
setblock ~39~9~82 ice
setblock ~39~9~82 ice 0
setblock ~40~9~82 ice
setblock ~40~9~82 ice 0
setblock ~41~9~82 ice
setblock ~41~9~82 ice 0
setblock ~42~9~82 ice
setblock ~42~9~82 ice 0
setblock ~43~9~82 ice
setblock ~43~9~82 ice 0
setblock ~44~9~82 ice
setblock ~44~9~82 ice 0
setblock ~45~9~82 ice
setblock ~45~9~82 ice 0
setblock ~3~9~83 ice
setblock ~3~9~83 ice 0
setblock ~4~9~83 ice
setblock ~4~9~83 ice 0
setblock ~5~9~83 ice
setblock ~5~9~83 ice 0
setblock ~6~9~83 ice
setblock ~6~9~83 ice 0
setblock ~7~9~83 ice
setblock ~7~9~83 ice 0
setblock ~8~9~83 ice
setblock ~8~9~83 ice 0
setblock ~9~9~83 ice
setblock ~9~9~83 ice 0
setblock ~10~9~83 ice
setblock ~10~9~83 ice 0
setblock ~11~9~83 ice
setblock ~11~9~83 ice 0
setblock ~12~9~83 ice
setblock ~12~9~83 ice 0
setblock ~37~9~83 ice
setblock ~37~9~83 ice 0
setblock ~38~9~83 ice
setblock ~38~9~83 ice 0
setblock ~39~9~83 ice
setblock ~39~9~83 ice 0
setblock ~40~9~83 ice
setblock ~40~9~83 ice 0
setblock ~41~9~83 ice
setblock ~41~9~83 ice 0
setblock ~42~9~83 ice
setblock ~42~9~83 ice 0
setblock ~43~9~83 ice
setblock ~43~9~83 ice 0
setblock ~44~9~83 ice
setblock ~44~9~83 ice 0
setblock ~45~9~83 ice
setblock ~45~9~83 ice 0
setblock ~46~9~83 ice
setblock ~46~9~83 ice 0
setblock ~47~9~83 ice
setblock ~47~9~83 ice 0
setblock ~3~9~84 ice
setblock ~3~9~84 ice 0
setblock ~4~9~84 ice
setblock ~4~9~84 ice 0
setblock ~5~9~84 ice
setblock ~5~9~84 ice 0
setblock ~6~9~84 ice
setblock ~6~9~84 ice 0
setblock ~7~9~84 ice
setblock ~7~9~84 ice 0
setblock ~8~9~84 ice
setblock ~8~9~84 ice 0
setblock ~9~9~84 ice
setblock ~9~9~84 ice 0
setblock ~10~9~84 ice
setblock ~10~9~84 ice 0
setblock ~11~9~84 ice
setblock ~11~9~84 ice 0
setblock ~37~9~84 ice
setblock ~37~9~84 ice 0
setblock ~38~9~84 ice
setblock ~38~9~84 ice 0
setblock ~39~9~84 ice
setblock ~39~9~84 ice 0
setblock ~40~9~84 ice
setblock ~40~9~84 ice 0
setblock ~41~9~84 ice
setblock ~41~9~84 ice 0
setblock ~42~9~84 ice
setblock ~42~9~84 ice 0
setblock ~43~9~84 ice
setblock ~43~9~84 ice 0
setblock ~44~9~84 ice
setblock ~44~9~84 ice 0
setblock ~45~9~84 ice
setblock ~45~9~84 ice 0
setblock ~46~9~84 ice
setblock ~46~9~84 ice 0
setblock ~47~9~84 ice
setblock ~47~9~84 ice 0
setblock ~48~9~84 ice
setblock ~48~9~84 ice 0
setblock ~4~9~85 ice
setblock ~4~9~85 ice 0
setblock ~5~9~85 ice
setblock ~5~9~85 ice 0
setblock ~6~9~85 ice
setblock ~6~9~85 ice 0
setblock ~7~9~85 ice
setblock ~7~9~85 ice 0
setblock ~8~9~85 ice
setblock ~8~9~85 ice 0
setblock ~9~9~85 ice
setblock ~9~9~85 ice 0
setblock ~10~9~85 ice
setblock ~10~9~85 ice 0
setblock ~37~9~85 ice
setblock ~37~9~85 ice 0
setblock ~38~9~85 ice
setblock ~38~9~85 ice 0
setblock ~39~9~85 ice
setblock ~39~9~85 ice 0
setblock ~40~9~85 ice
setblock ~40~9~85 ice 0
setblock ~41~9~85 ice
setblock ~41~9~85 ice 0
setblock ~42~9~85 ice
setblock ~42~9~85 ice 0
setblock ~43~9~85 ice
setblock ~43~9~85 ice 0
setblock ~44~9~85 ice
setblock ~44~9~85 ice 0
setblock ~45~9~85 ice
setblock ~45~9~85 ice 0
setblock ~46~9~85 ice
setblock ~46~9~85 ice 0
setblock ~47~9~85 ice
setblock ~47~9~85 ice 0
setblock ~48~9~85 ice
setblock ~48~9~85 ice 0
setblock ~6~9~86 ice
setblock ~6~9~86 ice 0
setblock ~7~9~86 ice
setblock ~7~9~86 ice 0
setblock ~8~9~86 ice
setblock ~8~9~86 ice 0
setblock ~39~9~86 ice
setblock ~39~9~86 ice 0
setblock ~40~9~86 ice
setblock ~40~9~86 ice 0
setblock ~41~9~86 ice
setblock ~41~9~86 ice 0
setblock ~42~9~86 ice
setblock ~42~9~86 ice 0
setblock ~43~9~86 ice
setblock ~43~9~86 ice 0
